Windows PowerShell
Copyright (C) Microsoft Corporation. All rights reserved.

Try the new cross-platform PowerShell https://aka.ms/pscore6

PS C:\Users\romanpc> cd ..
PS C:\Users> ls


    Directory: C:\Users


Mode                LastWriteTime         Length Name
----                -------------         ------ ----
d-----         3/6/2017   8:36 PM                Default.migrated
d-----       10/13/2020   9:55 PM                postgres
d-r---        8/29/2019   7:04 AM                Public
d-----       10/12/2020   7:54 PM                romanpc


PS C:\Users> cd romanpc
PS C:\Users\romanpc> ls


    Directory: C:\Users\romanpc


Mode                LastWriteTime         Length Name
----                -------------         ------ ----
d-----        10/6/2020   8:56 PM                .conda
d-----        8/29/2018   9:39 PM                .idlerc
d-----       12/19/2018   8:03 PM                .jagex_cache_32
d-----         9/2/2018   6:32 PM                .pylint.d
d-----       11/17/2019   6:41 PM                .RapidMiner
d-----        1/11/2020  12:15 AM                .VirtualBox
d-----        9/13/2020   3:34 PM                .vscode
d-r---       10/14/2020   8:44 AM                3D Objects
d-----       11/27/2019  12:27 AM                ansel
d-----        8/25/2019  10:18 PM                Apple
d-r---       10/14/2020   8:44 AM                Contacts
d-r---       10/14/2020   8:44 AM                Desktop
d-----       10/18/2020   2:48 PM                Dev
d-r---       10/14/2020   8:44 AM                Documents
d-r---       10/18/2020   2:40 PM                Downloads
d-r---       10/14/2020   8:44 AM                Favorites
d-----         3/6/2017   1:09 PM                Intel
d-----       12/19/2018   8:03 PM                jagexcache
d-r---       10/14/2020   8:44 AM                Links
d-r---       10/14/2020   8:44 AM                Music
dar--l       10/15/2020   2:57 PM                OneDrive
d-r---       10/14/2020   8:44 AM                Pictures
d-r---       10/14/2020   8:44 AM                Saved Games
d-r---       10/14/2020   8:44 AM                Searches
d-----         9/2/2018   6:17 PM                source
d-r---       10/18/2020   2:02 PM                Videos
d-----        7/27/2017   7:19 PM                VirtualBox VMs
-a----       10/14/2018   3:32 PM           8975 .bash_history
-a----        9/13/2018  11:31 PM            115 .gitconfig
-a----         9/1/2018   9:20 PM           1098 .viminfo
-a----         9/2/2018   7:08 PM              0 activate
-a----        9/13/2020   2:38 PM       65538032 edb_languagepack.exe
-a----        9/13/2020   2:38 PM       14536096 edb_mtk.exe
-a----        9/13/2020   2:38 PM       12870368 edb_npgsql.exe
-a----        9/13/2020   2:38 PM       20621256 edb_pem_agent.exe
-a----        9/13/2020   2:38 PM      432052272 edb_pem_server.exe
-a----        9/13/2020   2:39 PM       11696272 edb_pem_sqlprofiler_pg12.exe
-a----        9/13/2020   2:39 PM       11928264 edb_pgagent_pg12.exe
-a----        9/13/2020   2:39 PM       22082632 edb_pgbouncer.exe
-a----        9/13/2020   2:39 PM       14160584 edb_pgjdbc.exe
-a----        9/13/2020   2:39 PM       21126576 edb_psqlodbc.exe
-a----        9/13/2020   2:39 PM       11947648 edb_slony_i_pg12.exe
-a----        9/13/2020   2:39 PM       11913560 edb_sqlprotect_pg12.exe
-a----        9/13/2020   2:39 PM       47514840 edb_xdb_62.exe
-a----        8/29/2018   9:31 PM              0 geckodriver.log
-a----        7/14/2019   1:35 AM             24 jagexappletviewer.preferences
-a----        4/23/2020  10:13 PM             46 jagex_cl_oldschool_LIVE.dat
-a----        9/13/2020   2:39 PM       45337648 pemhttpd.exe
-a----        9/13/2020   2:39 PM       36577873 postgis_3_0_pg12.exe
-a----        4/23/2020  10:13 PM             24 random.dat


PS C:\Users\romanpc> cd dev
PS C:\Users\romanpc\dev> ls


    Directory: C:\Users\romanpc\dev


Mode                LastWriteTime         Length Name
----                -------------         ------ ----
d-----         9/8/2020  10:21 PM                cfehome
d-----       10/18/2020   2:47 PM                env
d-----       10/12/2020   7:56 PM                GitHub
d-----       10/12/2020   7:58 PM                GitHub - Copy
d-----       10/18/2020   2:45 PM                GithubBookmarksStuff
-a----       10/18/2020   2:40 PM        9320687 CIDM6325-master.zip
-a----       10/12/2020   8:00 PM       31648439 GitHub - Assignment 4.5.rar


PS C:\Users\romanpc\dev> cd env
PS C:\Users\romanpc\dev\env> Python -m venv
usage: venv [-h] [--system-site-packages] [--symlinks | --copies] [--clear] [--upgrade] [--without-pip]
            [--prompt PROMPT]
            ENV_DIR [ENV_DIR ...]
venv: error: the following arguments are required: ENV_DIR
PS C:\Users\romanpc\dev\env> Python -m venv env/bookmarks
PS C:\Users\romanpc\dev\env>
PS C:\Users\romanpc\dev\env> ls


    Directory: C:\Users\romanpc\dev\env


Mode                LastWriteTime         Length Name
----                -------------         ------ ----
d-----       10/18/2020   2:59 PM                env


PS C:\Users\romanpc\dev\env> cd env
PS C:\Users\romanpc\dev\env\env> ls


    Directory: C:\Users\romanpc\dev\env\env


Mode                LastWriteTime         Length Name
----                -------------         ------ ----
d-----       10/18/2020   2:59 PM                bookmarks


PS C:\Users\romanpc\dev\env\env> cd bookmarks
PS C:\Users\romanpc\dev\env\env\bookmarks> ls


    Directory: C:\Users\romanpc\dev\env\env\bookmarks


Mode                LastWriteTime         Length Name
----                -------------         ------ ----
d-----       10/18/2020   2:59 PM                Include
d-----       10/18/2020   2:59 PM                Lib
d-----       10/18/2020   2:59 PM                Scripts
-a----       10/18/2020   2:59 PM             75 pyvenv.cfg


PS C:\Users\romanpc\dev\env\env\bookmarks> cd ./Scripts/activate
cd : Cannot find path './Scripts/activate' because it does not exist.
At line:1 char:1
+ cd ./Scripts/activate
+ ~~~~~~~~~~~~~~~~~~~~~
    + CategoryInfo          : ObjectNotFound: (./Scripts/activate:String) [Set-Location], ItemNotFoundException
    + FullyQualifiedErrorId : PathNotFound,Microsoft.PowerShell.Commands.SetLocationCommand

PS C:\Users\romanpc\dev\env\env\bookmarks> ./Scripts/activate
(bookmarks) PS C:\Users\romanpc\dev\env\env\bookmarks> ls


    Directory: C:\Users\romanpc\dev\env\env\bookmarks


Mode                LastWriteTime         Length Name
----                -------------         ------ ----
d-----       10/18/2020   2:59 PM                Include
d-----       10/18/2020   2:59 PM                Lib
d-----       10/18/2020   2:59 PM                Scripts
-a----       10/18/2020   2:59 PM             75 pyvenv.cfg


(bookmarks) PS C:\Users\romanpc\dev\env\env\bookmarks> Pip install django
Collecting django
  Using cached Django-3.1.2-py3-none-any.whl (7.8 MB)
Collecting pytz
  Using cached pytz-2020.1-py2.py3-none-any.whl (510 kB)
Collecting asgiref~=3.2.10
  Using cached asgiref-3.2.10-py3-none-any.whl (19 kB)
Collecting sqlparse>=0.2.2
  Using cached sqlparse-0.4.1-py3-none-any.whl (42 kB)
Installing collected packages: pytz, asgiref, sqlparse, django
Successfully installed asgiref-3.2.10 django-3.1.2 pytz-2020.1 sqlparse-0.4.1
WARNING: You are using pip version 20.1.1; however, version 20.2.4 is available.
You should consider upgrading via the 'c:\users\romanpc\dev\env\env\bookmarks\scripts\python.exe -m pip install --upgrade pip' command.
(bookmarks) PS C:\Users\romanpc\dev\env\env\bookmarks> django-admin startproject bookmarks
(bookmarks) PS C:\Users\romanpc\dev\env\env\bookmarks> ls


    Directory: C:\Users\romanpc\dev\env\env\bookmarks


Mode                LastWriteTime         Length Name
----                -------------         ------ ----
d-----       10/18/2020   3:01 PM                bookmarks
d-----       10/18/2020   2:59 PM                Include
d-----       10/18/2020   2:59 PM                Lib
d-----       10/18/2020   3:01 PM                Scripts
-a----       10/18/2020   2:59 PM             75 pyvenv.cfg


(bookmarks) PS C:\Users\romanpc\dev\env\env\bookmarks> cd bookmarks
(bookmarks) PS C:\Users\romanpc\dev\env\env\bookmarks\bookmarks> ls


    Directory: C:\Users\romanpc\dev\env\env\bookmarks\bookmarks


Mode                LastWriteTime         Length Name
----                -------------         ------ ----
d-----       10/18/2020   3:01 PM                bookmarks
-a----       10/18/2020   3:01 PM            687 manage.py


(bookmarks) PS C:\Users\romanpc\dev\env\env\bookmarks\bookmarks> django-admin startapp account
(bookmarks) PS C:\Users\romanpc\dev\env\env\bookmarks\bookmarks> ls


    Directory: C:\Users\romanpc\dev\env\env\bookmarks\bookmarks


Mode                LastWriteTime         Length Name
----                -------------         ------ ----
d-----       10/18/2020   3:01 PM                account
d-----       10/18/2020   3:01 PM                bookmarks
-a----       10/18/2020   3:01 PM            687 manage.py


(bookmarks) PS C:\Users\romanpc\dev\env\env\bookmarks\bookmarks> python manage.py migrate
Operations to perform:
  Apply all migrations: admin, auth, contenttypes, sessions
Running migrations:
  Applying contenttypes.0001_initial... OK
  Applying auth.0001_initial... OK
  Applying admin.0001_initial... OK
  Applying admin.0002_logentry_remove_auto_add... OK
  Applying admin.0003_logentry_add_action_flag_choices... OK
  Applying contenttypes.0002_remove_content_type_name... OK
  Applying auth.0002_alter_permission_name_max_length... OK
  Applying auth.0003_alter_user_email_max_length... OK
  Applying auth.0004_alter_user_username_opts... OK
  Applying auth.0005_alter_user_last_login_null... OK
  Applying auth.0006_require_contenttypes_0002... OK
  Applying auth.0007_alter_validators_add_error_messages... OK
  Applying auth.0008_alter_user_username_max_length... OK
  Applying auth.0009_alter_user_last_name_max_length... OK
  Applying auth.0010_alter_group_name_max_length... OK
  Applying auth.0011_update_proxy_permissions... OK
  Applying auth.0012_alter_user_first_name_max_length... OK
  Applying sessions.0001_initial... OK
(bookmarks) PS C:\Users\romanpc\dev\env\env\bookmarks\bookmarks> python manage.py runserver
Watching for file changes with StatReloader
Performing system checks...

Exception in thread django-main-thread:
Traceback (most recent call last):
  File "C:\Python38\lib\threading.py", line 932, in _bootstrap_inner
    self.run()
  File "C:\Python38\lib\threading.py", line 870, in run
    self._target(*self._args, **self._kwargs)
  File "C:\Users\romanpc\dev\env\env\bookmarks\lib\site-packages\django\utils\autoreload.py", line 53, in wrapper
    fn(*args, **kwargs)
  File "C:\Users\romanpc\dev\env\env\bookmarks\lib\site-packages\django\core\management\commands\runserver.py", line 118, in inner_run
    self.check(display_num_errors=True)
  File "C:\Users\romanpc\dev\env\env\bookmarks\lib\site-packages\django\core\management\base.py", line 392, in check
    all_issues = checks.run_checks(
  File "C:\Users\romanpc\dev\env\env\bookmarks\lib\site-packages\django\core\checks\registry.py", line 70, in run_checks
    new_errors = check(app_configs=app_configs, databases=databases)
  File "C:\Users\romanpc\dev\env\env\bookmarks\lib\site-packages\django\core\checks\urls.py", line 40, in check_url_namespaces_unique
    all_namespaces = _load_all_namespaces(resolver)
  File "C:\Users\romanpc\dev\env\env\bookmarks\lib\site-packages\django\core\checks\urls.py", line 57, in _load_all_namespaces
    url_patterns = getattr(resolver, 'url_patterns', [])
  File "C:\Users\romanpc\dev\env\env\bookmarks\lib\site-packages\django\utils\functional.py", line 48, in __get__
    res = instance.__dict__[self.name] = self.func(instance)
  File "C:\Users\romanpc\dev\env\env\bookmarks\lib\site-packages\django\urls\resolvers.py", line 589, in url_patterns
    patterns = getattr(self.urlconf_module, "urlpatterns", self.urlconf_module)
  File "C:\Users\romanpc\dev\env\env\bookmarks\lib\site-packages\django\utils\functional.py", line 48, in __get__
    res = instance.__dict__[self.name] = self.func(instance)
  File "C:\Users\romanpc\dev\env\env\bookmarks\lib\site-packages\django\urls\resolvers.py", line 582, in urlconf_module
    return import_module(self.urlconf_name)
  File "C:\Python38\lib\importlib\__init__.py", line 127, in import_module
    return _bootstrap._gcd_import(name[level:], package, level)
  File "<frozen importlib._bootstrap>", line 1014, in _gcd_import
  File "<frozen importlib._bootstrap>", line 991, in _find_and_load
  File "<frozen importlib._bootstrap>", line 975, in _find_and_load_unlocked
  File "<frozen importlib._bootstrap>", line 671, in _load_unlocked
  File "<frozen importlib._bootstrap_external>", line 783, in exec_module
  File "<frozen importlib._bootstrap>", line 219, in _call_with_frames_removed
  File "C:\Users\romanpc\dev\env\env\bookmarks\bookmarks\bookmarks\urls.py", line 23, in <module>
    path('account/', include('account.urls')),
  File "C:\Users\romanpc\dev\env\env\bookmarks\lib\site-packages\django\urls\conf.py", line 34, in include
    urlconf_module = import_module(urlconf_module)
  File "C:\Python38\lib\importlib\__init__.py", line 127, in import_module
    return _bootstrap._gcd_import(name[level:], package, level)
  File "<frozen importlib._bootstrap>", line 1014, in _gcd_import
  File "<frozen importlib._bootstrap>", line 991, in _find_and_load
  File "<frozen importlib._bootstrap>", line 975, in _find_and_load_unlocked
  File "<frozen importlib._bootstrap>", line 671, in _load_unlocked
  File "<frozen importlib._bootstrap_external>", line 783, in exec_module
  File "<frozen importlib._bootstrap>", line 219, in _call_with_frames_removed
  File "C:\Users\romanpc\dev\env\env\bookmarks\bookmarks\account\urls.py", line 2, in <module>
    from . import views
  File "C:\Users\romanpc\dev\env\env\bookmarks\bookmarks\account\views.py", line 22
    else:
    ^
IndentationError: unexpected indent
(bookmarks) PS C:\Users\romanpc\dev\env\env\bookmarks\bookmarks> python manage.py runserver
Watching for file changes with StatReloader
Performing system checks...

Exception in thread django-main-thread:
Traceback (most recent call last):
  File "C:\Python38\lib\threading.py", line 932, in _bootstrap_inner
    self.run()
  File "C:\Python38\lib\threading.py", line 870, in run
    self._target(*self._args, **self._kwargs)
  File "C:\Users\romanpc\dev\env\env\bookmarks\lib\site-packages\django\utils\autoreload.py", line 53, in wrapper
    fn(*args, **kwargs)
  File "C:\Users\romanpc\dev\env\env\bookmarks\lib\site-packages\django\core\management\commands\runserver.py", line 118, in inner_run
    self.check(display_num_errors=True)
  File "C:\Users\romanpc\dev\env\env\bookmarks\lib\site-packages\django\core\management\base.py", line 392, in check
    all_issues = checks.run_checks(
  File "C:\Users\romanpc\dev\env\env\bookmarks\lib\site-packages\django\core\checks\registry.py", line 70, in run_checks
    new_errors = check(app_configs=app_configs, databases=databases)
  File "C:\Users\romanpc\dev\env\env\bookmarks\lib\site-packages\django\core\checks\urls.py", line 40, in check_url_namespaces_unique
    all_namespaces = _load_all_namespaces(resolver)
  File "C:\Users\romanpc\dev\env\env\bookmarks\lib\site-packages\django\core\checks\urls.py", line 57, in _load_all_namespaces
    url_patterns = getattr(resolver, 'url_patterns', [])
  File "C:\Users\romanpc\dev\env\env\bookmarks\lib\site-packages\django\utils\functional.py", line 48, in __get__
    res = instance.__dict__[self.name] = self.func(instance)
  File "C:\Users\romanpc\dev\env\env\bookmarks\lib\site-packages\django\urls\resolvers.py", line 589, in url_patterns
    patterns = getattr(self.urlconf_module, "urlpatterns", self.urlconf_module)
  File "C:\Users\romanpc\dev\env\env\bookmarks\lib\site-packages\django\utils\functional.py", line 48, in __get__
    res = instance.__dict__[self.name] = self.func(instance)
  File "C:\Users\romanpc\dev\env\env\bookmarks\lib\site-packages\django\urls\resolvers.py", line 582, in urlconf_module
    return import_module(self.urlconf_name)
  File "C:\Python38\lib\importlib\__init__.py", line 127, in import_module
    return _bootstrap._gcd_import(name[level:], package, level)
  File "<frozen importlib._bootstrap>", line 1014, in _gcd_import
  File "<frozen importlib._bootstrap>", line 991, in _find_and_load
  File "<frozen importlib._bootstrap>", line 975, in _find_and_load_unlocked
  File "<frozen importlib._bootstrap>", line 671, in _load_unlocked
  File "<frozen importlib._bootstrap_external>", line 783, in exec_module
  File "<frozen importlib._bootstrap>", line 219, in _call_with_frames_removed
  File "C:\Users\romanpc\dev\env\env\bookmarks\bookmarks\bookmarks\urls.py", line 23, in <module>
    path('account/', include('account.urls')),
  File "C:\Users\romanpc\dev\env\env\bookmarks\lib\site-packages\django\urls\conf.py", line 34, in include
    urlconf_module = import_module(urlconf_module)
  File "C:\Python38\lib\importlib\__init__.py", line 127, in import_module
    return _bootstrap._gcd_import(name[level:], package, level)
  File "<frozen importlib._bootstrap>", line 1014, in _gcd_import
  File "<frozen importlib._bootstrap>", line 991, in _find_and_load
  File "<frozen importlib._bootstrap>", line 975, in _find_and_load_unlocked
  File "<frozen importlib._bootstrap>", line 671, in _load_unlocked
  File "<frozen importlib._bootstrap_external>", line 783, in exec_module
  File "<frozen importlib._bootstrap>", line 219, in _call_with_frames_removed
  File "C:\Users\romanpc\dev\env\env\bookmarks\bookmarks\account\urls.py", line 2, in <module>
    from . import views
  File "C:\Users\romanpc\dev\env\env\bookmarks\bookmarks\account\views.py", line 5, in <module>
    from .forms import LoginForm
  File "C:\Users\romanpc\dev\env\env\bookmarks\bookmarks\account\forms.py", line 4
    password =
             ^
SyntaxError: invalid syntax
C:\Users\romanpc\Dev\env\env\bookmarks\bookmarks\account\forms.py changed, reloading.
Watching for file changes with StatReloader
Performing system checks...

System check identified no issues (0 silenced).
October 18, 2020 - 15:41:37
Django version 3.1.2, using settings 'bookmarks.settings'
Starting development server at http://127.0.0.1:8000/
Quit the server with CTRL-BREAK.
Not Found: /
[18/Oct/2020 15:42:10] "GET / HTTP/1.1" 404 2032
Not Found: /favicon.ico
[18/Oct/2020 15:42:10] "GET /favicon.ico HTTP/1.1" 404 2083
Not Found: /
[18/Oct/2020 15:42:12] "GET / HTTP/1.1" 404 2032
(bookmarks) PS C:\Users\romanpc\dev\env\env\bookmarks\bookmarks> python manage.py runserver
Watching for file changes with StatReloader
Performing system checks...

System check identified no issues (0 silenced).
October 18, 2020 - 15:42:26
Django version 3.1.2, using settings 'bookmarks.settings'
Starting development server at http://127.0.0.1:8000/
Quit the server with CTRL-BREAK.
Not Found: /
[18/Oct/2020 15:42:30] "GET / HTTP/1.1" 404 2032
(bookmarks) PS C:\Users\romanpc\dev\env\env\bookmarks\bookmarks> python manage.py runserver
Watching for file changes with StatReloader
Performing system checks...

System check identified no issues (0 silenced).
October 18, 2020 - 15:42:44
Django version 3.1.2, using settings 'bookmarks.settings'
Starting development server at http://127.0.0.1:8000/
Quit the server with CTRL-BREAK.
(bookmarks) PS C:\Users\romanpc\dev\env\env\bookmarks\bookmarks> python manage.py createsuperuser
Username (leave blank to use 'romanpc'): romancherednik
Email address: romancherednik@gmail.com
Password:
Password (again):
Superuser created successfully.
(bookmarks) PS C:\Users\romanpc\dev\env\env\bookmarks\bookmarks> python manage.py runserver
Watching for file changes with StatReloader
Performing system checks...

System check identified no issues (0 silenced).
October 18, 2020 - 15:44:17
Django version 3.1.2, using settings 'bookmarks.settings'
Starting development server at http://127.0.0.1:8000/
Quit the server with CTRL-BREAK.
Not Found: /
[18/Oct/2020 15:44:27] "GET / HTTP/1.1" 404 2032
Not Found: /
[18/Oct/2020 15:44:28] "GET / HTTP/1.1" 404 2032
C:\Users\romanpc\Dev\env\env\bookmarks\bookmarks\account\urls.py changed, reloading.
Watching for file changes with StatReloader
Performing system checks...

Exception in thread django-main-thread:
Traceback (most recent call last):
  File "C:\Python38\lib\threading.py", line 932, in _bootstrap_inner
    self.run()
  File "C:\Python38\lib\threading.py", line 870, in run
    self._target(*self._args, **self._kwargs)
  File "C:\Users\romanpc\dev\env\env\bookmarks\lib\site-packages\django\utils\autoreload.py", line 53, in wrapper
    fn(*args, **kwargs)
  File "C:\Users\romanpc\dev\env\env\bookmarks\lib\site-packages\django\core\management\commands\runserver.py", line 118, in inner_run
    self.check(display_num_errors=True)
  File "C:\Users\romanpc\dev\env\env\bookmarks\lib\site-packages\django\core\management\base.py", line 392, in check
    all_issues = checks.run_checks(
  File "C:\Users\romanpc\dev\env\env\bookmarks\lib\site-packages\django\core\checks\registry.py", line 70, in run_checks
    new_errors = check(app_configs=app_configs, databases=databases)
  File "C:\Users\romanpc\dev\env\env\bookmarks\lib\site-packages\django\core\checks\urls.py", line 13, in check_url_config
    return check_resolver(resolver)
  File "C:\Users\romanpc\dev\env\env\bookmarks\lib\site-packages\django\core\checks\urls.py", line 23, in check_resolver
    return check_method()
  File "C:\Users\romanpc\dev\env\env\bookmarks\lib\site-packages\django\urls\resolvers.py", line 408, in check
    for pattern in self.url_patterns:
  File "C:\Users\romanpc\dev\env\env\bookmarks\lib\site-packages\django\utils\functional.py", line 48, in __get__
    res = instance.__dict__[self.name] = self.func(instance)
  File "C:\Users\romanpc\dev\env\env\bookmarks\lib\site-packages\django\urls\resolvers.py", line 589, in url_patterns
    patterns = getattr(self.urlconf_module, "urlpatterns", self.urlconf_module)
  File "C:\Users\romanpc\dev\env\env\bookmarks\lib\site-packages\django\utils\functional.py", line 48, in __get__
    res = instance.__dict__[self.name] = self.func(instance)
  File "C:\Users\romanpc\dev\env\env\bookmarks\lib\site-packages\django\urls\resolvers.py", line 582, in urlconf_module
    return import_module(self.urlconf_name)
  File "C:\Python38\lib\importlib\__init__.py", line 127, in import_module
    return _bootstrap._gcd_import(name[level:], package, level)
  File "<frozen importlib._bootstrap>", line 1014, in _gcd_import
  File "<frozen importlib._bootstrap>", line 991, in _find_and_load
  File "<frozen importlib._bootstrap>", line 975, in _find_and_load_unlocked
  File "<frozen importlib._bootstrap>", line 671, in _load_unlocked
  File "<frozen importlib._bootstrap_external>", line 783, in exec_module
  File "<frozen importlib._bootstrap>", line 219, in _call_with_frames_removed
  File "C:\Users\romanpc\dev\env\env\bookmarks\bookmarks\bookmarks\urls.py", line 23, in <module>
    path('account/', include('account.urls')),
  File "C:\Users\romanpc\dev\env\env\bookmarks\lib\site-packages\django\urls\conf.py", line 34, in include
    urlconf_module = import_module(urlconf_module)
  File "C:\Python38\lib\importlib\__init__.py", line 127, in import_module
    return _bootstrap._gcd_import(name[level:], package, level)
  File "<frozen importlib._bootstrap>", line 1014, in _gcd_import
  File "<frozen importlib._bootstrap>", line 991, in _find_and_load
  File "<frozen importlib._bootstrap>", line 975, in _find_and_load_unlocked
  File "<frozen importlib._bootstrap>", line 671, in _load_unlocked
  File "<frozen importlib._bootstrap_external>", line 783, in exec_module
  File "<frozen importlib._bootstrap>", line 219, in _call_with_frames_removed
  File "C:\Users\romanpc\dev\env\env\bookmarks\bookmarks\account\urls.py", line 8, in <module>
    path('', views.dashboard, name='dashboard'),
AttributeError: module 'account.views' has no attribute 'dashboard'
C:\Users\romanpc\Dev\env\env\bookmarks\bookmarks\account\urls.py changed, reloading.
Watching for file changes with StatReloader
Performing system checks...

System check identified no issues (0 silenced).
October 18, 2020 - 15:47:37
Django version 3.1.2, using settings 'bookmarks.settings'
Starting development server at http://127.0.0.1:8000/
Quit the server with CTRL-BREAK.
Not Found: /
[18/Oct/2020 15:47:42] "GET / HTTP/1.1" 404 2032
Not Found: /
[18/Oct/2020 15:47:43] "GET / HTTP/1.1" 404 2032
(bookmarks) PS C:\Users\romanpc\dev\env\env\bookmarks\bookmarks> python manage.py runserver
Watching for file changes with StatReloader
Performing system checks...

System check identified no issues (0 silenced).
October 18, 2020 - 16:26:48
Django version 3.1.2, using settings 'bookmarks.settings'
Starting development server at http://127.0.0.1:8000/
Quit the server with CTRL-BREAK.
Not Found: /
[18/Oct/2020 16:26:52] "GET / HTTP/1.1" 404 2032
Not Found: /
[18/Oct/2020 16:26:53] "GET / HTTP/1.1" 404 2032
Not Found: /
[18/Oct/2020 16:26:57] "GET / HTTP/1.1" 404 2032
(bookmarks) PS C:\Users\romanpc\dev\env\env\bookmarks\bookmarks> python manage.py runserver
Watching for file changes with StatReloader
Performing system checks...

System check identified no issues (0 silenced).
October 18, 2020 - 16:28:21
Django version 3.1.2, using settings 'bookmarks.settings'
Starting development server at http://127.0.0.1:8000/
Quit the server with CTRL-BREAK.
C:\Users\romanpc\Dev\env\env\bookmarks\bookmarks\bookmarks\urls.py changed, reloading.
Watching for file changes with StatReloader
Performing system checks...

System check identified no issues (0 silenced).
October 18, 2020 - 16:28:23
Django version 3.1.2, using settings 'bookmarks.settings'
Starting development server at http://127.0.0.1:8000/
Quit the server with CTRL-BREAK.
Not Found: /
[18/Oct/2020 16:28:26] "GET / HTTP/1.1" 404 2032
Not Found: /
[18/Oct/2020 16:28:27] "GET / HTTP/1.1" 404 2032
C:\Users\romanpc\Dev\env\env\bookmarks\bookmarks\bookmarks\urls.py changed, reloading.
Watching for file changes with StatReloader
Performing system checks...

Exception in thread django-main-thread:
Traceback (most recent call last):
  File "C:\Python38\lib\threading.py", line 932, in _bootstrap_inner
    self.run()
  File "C:\Python38\lib\threading.py", line 870, in run
    self._target(*self._args, **self._kwargs)
  File "C:\Users\romanpc\dev\env\env\bookmarks\lib\site-packages\django\utils\autoreload.py", line 53, in wrapper
    fn(*args, **kwargs)
  File "C:\Users\romanpc\dev\env\env\bookmarks\lib\site-packages\django\core\management\commands\runserver.py", line 118, in inner_run
    self.check(display_num_errors=True)
  File "C:\Users\romanpc\dev\env\env\bookmarks\lib\site-packages\django\core\management\base.py", line 392, in check
    all_issues = checks.run_checks(
  File "C:\Users\romanpc\dev\env\env\bookmarks\lib\site-packages\django\core\checks\registry.py", line 70, in run_checks
    new_errors = check(app_configs=app_configs, databases=databases)
  File "C:\Users\romanpc\dev\env\env\bookmarks\lib\site-packages\django\core\checks\urls.py", line 40, in check_url_namespaces_unique
    all_namespaces = _load_all_namespaces(resolver)
  File "C:\Users\romanpc\dev\env\env\bookmarks\lib\site-packages\django\core\checks\urls.py", line 57, in _load_all_namespaces
    url_patterns = getattr(resolver, 'url_patterns', [])
  File "C:\Users\romanpc\dev\env\env\bookmarks\lib\site-packages\django\utils\functional.py", line 48, in __get__
    res = instance.__dict__[self.name] = self.func(instance)
  File "C:\Users\romanpc\dev\env\env\bookmarks\lib\site-packages\django\urls\resolvers.py", line 589, in url_patterns
    patterns = getattr(self.urlconf_module, "urlpatterns", self.urlconf_module)
  File "C:\Users\romanpc\dev\env\env\bookmarks\lib\site-packages\django\utils\functional.py", line 48, in __get__
    res = instance.__dict__[self.name] = self.func(instance)
  File "C:\Users\romanpc\dev\env\env\bookmarks\lib\site-packages\django\urls\resolvers.py", line 582, in urlconf_module
    return import_module(self.urlconf_name)
  File "C:\Python38\lib\importlib\__init__.py", line 127, in import_module
    return _bootstrap._gcd_import(name[level:], package, level)
  File "<frozen importlib._bootstrap>", line 1014, in _gcd_import
  File "<frozen importlib._bootstrap>", line 991, in _find_and_load
  File "<frozen importlib._bootstrap>", line 975, in _find_and_load_unlocked
  File "<frozen importlib._bootstrap>", line 671, in _load_unlocked
  File "<frozen importlib._bootstrap_external>", line 783, in exec_module
  File "<frozen importlib._bootstrap>", line 219, in _call_with_frames_removed
  File "C:\Users\romanpc\dev\env\env\bookmarks\bookmarks\bookmarks\urls.py", line 23, in <module>
    path('', include('home.urls')),
  File "C:\Users\romanpc\dev\env\env\bookmarks\lib\site-packages\django\urls\conf.py", line 34, in include
    urlconf_module = import_module(urlconf_module)
  File "C:\Python38\lib\importlib\__init__.py", line 127, in import_module
    return _bootstrap._gcd_import(name[level:], package, level)
  File "<frozen importlib._bootstrap>", line 1014, in _gcd_import
  File "<frozen importlib._bootstrap>", line 991, in _find_and_load
  File "<frozen importlib._bootstrap>", line 961, in _find_and_load_unlocked
  File "<frozen importlib._bootstrap>", line 219, in _call_with_frames_removed
  File "<frozen importlib._bootstrap>", line 1014, in _gcd_import
  File "<frozen importlib._bootstrap>", line 991, in _find_and_load
  File "<frozen importlib._bootstrap>", line 973, in _find_and_load_unlocked
ModuleNotFoundError: No module named 'home'
Traceback (most recent call last):
  File "manage.py", line 22, in <module>
    main()
  File "manage.py", line 18, in main
    execute_from_command_line(sys.argv)
  File "C:\Users\romanpc\dev\env\env\bookmarks\lib\site-packages\django\core\management\__init__.py", line 401, in execute_from_command_line
    utility.execute()
  File "C:\Users\romanpc\dev\env\env\bookmarks\lib\site-packages\django\core\management\__init__.py", line 395, in execute
    self.fetch_command(subcommand).run_from_argv(self.argv)
  File "C:\Users\romanpc\dev\env\env\bookmarks\lib\site-packages\django\core\management\base.py", line 330, in run_from_argv
    self.execute(*args, **cmd_options)
  File "C:\Users\romanpc\dev\env\env\bookmarks\lib\site-packages\django\core\management\commands\runserver.py", line 61, in execute
    super().execute(*args, **options)
  File "C:\Users\romanpc\dev\env\env\bookmarks\lib\site-packages\django\core\management\base.py", line 371, in execute
    output = self.handle(*args, **options)
  File "C:\Users\romanpc\dev\env\env\bookmarks\lib\site-packages\django\core\management\commands\runserver.py", line 96, in handle
    self.run(**options)
  File "C:\Users\romanpc\dev\env\env\bookmarks\lib\site-packages\django\core\management\commands\runserver.py", line 103, in run
    autoreload.run_with_reloader(self.inner_run, **options)
  File "C:\Users\romanpc\dev\env\env\bookmarks\lib\site-packages\django\utils\autoreload.py", line 614, in run_with_reloader
    start_django(reloader, main_func, *args, **kwargs)
  File "C:\Users\romanpc\dev\env\env\bookmarks\lib\site-packages\django\utils\autoreload.py", line 599, in start_django
    reloader.run(django_main_thread)
  File "C:\Users\romanpc\dev\env\env\bookmarks\lib\site-packages\django\utils\autoreload.py", line 314, in run
    self.run_loop()
  File "C:\Users\romanpc\dev\env\env\bookmarks\lib\site-packages\django\utils\autoreload.py", line 320, in run_loop
    next(ticker)
  File "C:\Users\romanpc\dev\env\env\bookmarks\lib\site-packages\django\utils\autoreload.py", line 360, in tick
    for filepath, mtime in self.snapshot_files():
  File "C:\Users\romanpc\dev\env\env\bookmarks\lib\site-packages\django\utils\autoreload.py", line 376, in snapshot_files
    for file in self.watched_files():
  File "C:\Users\romanpc\dev\env\env\bookmarks\lib\site-packages\django\utils\autoreload.py", line 274, in watched_files
    yield from iter_all_python_module_files()
  File "C:\Users\romanpc\dev\env\env\bookmarks\lib\site-packages\django\utils\autoreload.py", line 105, in iter_all_python_module_files
    return iter_modules_and_files(modules, frozenset(_error_files))
  File "C:\Users\romanpc\dev\env\env\bookmarks\lib\site-packages\django\utils\autoreload.py", line 141, in iter_modules_and_files
    resolved_path = path.resolve(strict=True).absolute()
  File "C:\Python38\lib\pathlib.py", line 1177, in resolve
    s = self._flavour.resolve(self, strict=strict)
  File "C:\Python38\lib\pathlib.py", line 200, in resolve
    return self._ext_to_normal(_getfinalpathname(s))
OSError: [WinError 123] The filename, directory name, or volume label syntax is incorrect: '<frozen importlib._bootstrap>'
(bookmarks) PS C:\Users\romanpc\dev\env\env\bookmarks\bookmarks> python manage.py runserver
Watching for file changes with StatReloader
Performing system checks...

System check identified no issues (0 silenced).
October 18, 2020 - 16:29:32
Django version 3.1.2, using settings 'bookmarks.settings'
Starting development server at http://127.0.0.1:8000/
Quit the server with CTRL-BREAK.
C:\Users\romanpc\Dev\env\env\bookmarks\bookmarks\account\urls.py changed, reloading.
Watching for file changes with StatReloader
Performing system checks...

System check identified no issues (0 silenced).
October 18, 2020 - 16:32:52
Django version 3.1.2, using settings 'bookmarks.settings'
Starting development server at http://127.0.0.1:8000/
Quit the server with CTRL-BREAK.
(bookmarks) PS C:\Users\romanpc\dev\env\env\bookmarks\bookmarks> python manage.py runserver
Watching for file changes with StatReloader
Performing system checks...

System check identified no issues (0 silenced).
October 18, 2020 - 16:35:52
Django version 3.1.2, using settings 'bookmarks.settings'
Starting development server at http://127.0.0.1:8000/
Quit the server with CTRL-BREAK.
Not Found: /
[18/Oct/2020 16:35:58] "GET / HTTP/1.1" 404 2032
Not Found: /
[18/Oct/2020 16:35:59] "GET / HTTP/1.1" 404 2032
[18/Oct/2020 16:36:35] "GET /account/password_change/ HTTP/1.1" 302 0
[18/Oct/2020 16:36:35] "GET /account/login/?next=/account/password_change/ HTTP/1.1" 200 1108
[18/Oct/2020 16:36:35] "GET /static/css/base.css HTTP/1.1" 200 4515
[18/Oct/2020 16:37:13] "POST /account/login/ HTTP/1.1" 200 1301
[18/Oct/2020 16:37:21] "POST /account/login/ HTTP/1.1" 302 0
Internal Server Error: /account/password_change/
Traceback (most recent call last):
  File "C:\Users\romanpc\dev\env\env\bookmarks\lib\site-packages\django\urls\base.py", line 72, in reverse
    extra, resolver = resolver.namespace_dict[ns]
KeyError: 'images'

During handling of the above exception, another exception occurred:

Traceback (most recent call last):
  File "C:\Users\romanpc\dev\env\env\bookmarks\lib\site-packages\django\core\handlers\exception.py", line 47, in inner
    response = get_response(request)
  File "C:\Users\romanpc\dev\env\env\bookmarks\lib\site-packages\django\core\handlers\base.py", line 202, in _get_response
    response = response.render()
  File "C:\Users\romanpc\dev\env\env\bookmarks\lib\site-packages\django\template\response.py", line 105, in render
    self.content = self.rendered_content
  File "C:\Users\romanpc\dev\env\env\bookmarks\lib\site-packages\django\template\response.py", line 83, in rendered_content
    return template.render(context, self._request)
  File "C:\Users\romanpc\dev\env\env\bookmarks\lib\site-packages\django\template\backends\django.py", line 61, in render
    return self.template.render(context)
  File "C:\Users\romanpc\dev\env\env\bookmarks\lib\site-packages\django\template\base.py", line 170, in render
    return self._render(context)
  File "C:\Users\romanpc\dev\env\env\bookmarks\lib\site-packages\django\template\base.py", line 162, in _render
    return self.nodelist.render(context)
  File "C:\Users\romanpc\dev\env\env\bookmarks\lib\site-packages\django\template\base.py", line 938, in render
    bit = node.render_annotated(context)
  File "C:\Users\romanpc\dev\env\env\bookmarks\lib\site-packages\django\template\base.py", line 905, in render_annotated
    return self.render(context)
  File "C:\Users\romanpc\dev\env\env\bookmarks\lib\site-packages\django\template\loader_tags.py", line 150, in render
    return compiled_parent._render(context)
  File "C:\Users\romanpc\dev\env\env\bookmarks\lib\site-packages\django\template\base.py", line 162, in _render
    return self.nodelist.render(context)
  File "C:\Users\romanpc\dev\env\env\bookmarks\lib\site-packages\django\template\base.py", line 938, in render
    bit = node.render_annotated(context)
  File "C:\Users\romanpc\dev\env\env\bookmarks\lib\site-packages\django\template\base.py", line 905, in render_annotated
    return self.render(context)
  File "C:\Users\romanpc\dev\env\env\bookmarks\lib\site-packages\django\template\defaulttags.py", line 312, in render
    return nodelist.render(context)
  File "C:\Users\romanpc\dev\env\env\bookmarks\lib\site-packages\django\template\base.py", line 938, in render
    bit = node.render_annotated(context)
  File "C:\Users\romanpc\dev\env\env\bookmarks\lib\site-packages\django\template\base.py", line 905, in render_annotated
    return self.render(context)
  File "C:\Users\romanpc\dev\env\env\bookmarks\lib\site-packages\django\template\defaulttags.py", line 446, in render
    url = reverse(view_name, args=args, kwargs=kwargs, current_app=current_app)
  File "C:\Users\romanpc\dev\env\env\bookmarks\lib\site-packages\django\urls\base.py", line 83, in reverse
    raise NoReverseMatch("%s is not a registered namespace" % key)
django.urls.exceptions.NoReverseMatch: 'images' is not a registered namespace
[18/Oct/2020 16:37:21] "GET /account/password_change/ HTTP/1.1" 500 146002
Internal Server Error: /account/password_change/
Traceback (most recent call last):
  File "C:\Users\romanpc\dev\env\env\bookmarks\lib\site-packages\django\urls\base.py", line 72, in reverse
    extra, resolver = resolver.namespace_dict[ns]
KeyError: 'images'

During handling of the above exception, another exception occurred:

Traceback (most recent call last):
  File "C:\Users\romanpc\dev\env\env\bookmarks\lib\site-packages\django\core\handlers\exception.py", line 47, in inner
    response = get_response(request)
  File "C:\Users\romanpc\dev\env\env\bookmarks\lib\site-packages\django\core\handlers\base.py", line 202, in _get_response
    response = response.render()
  File "C:\Users\romanpc\dev\env\env\bookmarks\lib\site-packages\django\template\response.py", line 105, in render
    self.content = self.rendered_content
  File "C:\Users\romanpc\dev\env\env\bookmarks\lib\site-packages\django\template\response.py", line 83, in rendered_content
    return template.render(context, self._request)
  File "C:\Users\romanpc\dev\env\env\bookmarks\lib\site-packages\django\template\backends\django.py", line 61, in render
    return self.template.render(context)
  File "C:\Users\romanpc\dev\env\env\bookmarks\lib\site-packages\django\template\base.py", line 170, in render
    return self._render(context)
  File "C:\Users\romanpc\dev\env\env\bookmarks\lib\site-packages\django\template\base.py", line 162, in _render
    return self.nodelist.render(context)
  File "C:\Users\romanpc\dev\env\env\bookmarks\lib\site-packages\django\template\base.py", line 938, in render
    bit = node.render_annotated(context)
  File "C:\Users\romanpc\dev\env\env\bookmarks\lib\site-packages\django\template\base.py", line 905, in render_annotated
    return self.render(context)
  File "C:\Users\romanpc\dev\env\env\bookmarks\lib\site-packages\django\template\loader_tags.py", line 150, in render
    return compiled_parent._render(context)
  File "C:\Users\romanpc\dev\env\env\bookmarks\lib\site-packages\django\template\base.py", line 162, in _render
    return self.nodelist.render(context)
  File "C:\Users\romanpc\dev\env\env\bookmarks\lib\site-packages\django\template\base.py", line 938, in render
    bit = node.render_annotated(context)
  File "C:\Users\romanpc\dev\env\env\bookmarks\lib\site-packages\django\template\base.py", line 905, in render_annotated
    return self.render(context)
  File "C:\Users\romanpc\dev\env\env\bookmarks\lib\site-packages\django\template\defaulttags.py", line 312, in render
    return nodelist.render(context)
  File "C:\Users\romanpc\dev\env\env\bookmarks\lib\site-packages\django\template\base.py", line 938, in render
    bit = node.render_annotated(context)
  File "C:\Users\romanpc\dev\env\env\bookmarks\lib\site-packages\django\template\base.py", line 905, in render_annotated
    return self.render(context)
  File "C:\Users\romanpc\dev\env\env\bookmarks\lib\site-packages\django\template\defaulttags.py", line 446, in render
    url = reverse(view_name, args=args, kwargs=kwargs, current_app=current_app)
  File "C:\Users\romanpc\dev\env\env\bookmarks\lib\site-packages\django\urls\base.py", line 83, in reverse
    raise NoReverseMatch("%s is not a registered namespace" % key)
django.urls.exceptions.NoReverseMatch: 'images' is not a registered namespace
[18/Oct/2020 16:39:00] "GET /account/password_change/ HTTP/1.1" 500 145581
C:\Users\romanpc\Dev\env\env\bookmarks\bookmarks\account\urls.py changed, reloading.
Watching for file changes with StatReloader
Performing system checks...

Exception in thread django-main-thread:
Traceback (most recent call last):
  File "C:\Python38\lib\threading.py", line 932, in _bootstrap_inner
    self.run()
  File "C:\Python38\lib\threading.py", line 870, in run
    self._target(*self._args, **self._kwargs)
  File "C:\Users\romanpc\dev\env\env\bookmarks\lib\site-packages\django\utils\autoreload.py", line 53, in wrapper
    fn(*args, **kwargs)
  File "C:\Users\romanpc\dev\env\env\bookmarks\lib\site-packages\django\core\management\commands\runserver.py", line 118, in inner_run
    self.check(display_num_errors=True)
  File "C:\Users\romanpc\dev\env\env\bookmarks\lib\site-packages\django\core\management\base.py", line 392, in check
    all_issues = checks.run_checks(
  File "C:\Users\romanpc\dev\env\env\bookmarks\lib\site-packages\django\core\checks\registry.py", line 70, in run_checks
    new_errors = check(app_configs=app_configs, databases=databases)
  File "C:\Users\romanpc\dev\env\env\bookmarks\lib\site-packages\django\core\checks\urls.py", line 40, in check_url_namespaces_unique
    all_namespaces = _load_all_namespaces(resolver)
  File "C:\Users\romanpc\dev\env\env\bookmarks\lib\site-packages\django\core\checks\urls.py", line 57, in _load_all_namespaces
    url_patterns = getattr(resolver, 'url_patterns', [])
  File "C:\Users\romanpc\dev\env\env\bookmarks\lib\site-packages\django\utils\functional.py", line 48, in __get__
    res = instance.__dict__[self.name] = self.func(instance)
  File "C:\Users\romanpc\dev\env\env\bookmarks\lib\site-packages\django\urls\resolvers.py", line 589, in url_patterns
    patterns = getattr(self.urlconf_module, "urlpatterns", self.urlconf_module)
  File "C:\Users\romanpc\dev\env\env\bookmarks\lib\site-packages\django\utils\functional.py", line 48, in __get__
    res = instance.__dict__[self.name] = self.func(instance)
  File "C:\Users\romanpc\dev\env\env\bookmarks\lib\site-packages\django\urls\resolvers.py", line 582, in urlconf_module
    return import_module(self.urlconf_name)
  File "C:\Python38\lib\importlib\__init__.py", line 127, in import_module
    return _bootstrap._gcd_import(name[level:], package, level)
  File "<frozen importlib._bootstrap>", line 1014, in _gcd_import
  File "<frozen importlib._bootstrap>", line 991, in _find_and_load
  File "<frozen importlib._bootstrap>", line 975, in _find_and_load_unlocked
  File "<frozen importlib._bootstrap>", line 671, in _load_unlocked
  File "<frozen importlib._bootstrap_external>", line 783, in exec_module
  File "<frozen importlib._bootstrap>", line 219, in _call_with_frames_removed
  File "C:\Users\romanpc\dev\env\env\bookmarks\bookmarks\bookmarks\urls.py", line 24, in <module>
    path('account/', include('account.urls')),
  File "C:\Users\romanpc\dev\env\env\bookmarks\lib\site-packages\django\urls\conf.py", line 34, in include
    urlconf_module = import_module(urlconf_module)
  File "C:\Python38\lib\importlib\__init__.py", line 127, in import_module
    return _bootstrap._gcd_import(name[level:], package, level)
  File "<frozen importlib._bootstrap>", line 1014, in _gcd_import
  File "<frozen importlib._bootstrap>", line 991, in _find_and_load
  File "<frozen importlib._bootstrap>", line 975, in _find_and_load_unlocked
  File "<frozen importlib._bootstrap>", line 671, in _load_unlocked
  File "<frozen importlib._bootstrap_external>", line 779, in exec_module
  File "<frozen importlib._bootstrap_external>", line 916, in get_code
  File "<frozen importlib._bootstrap_external>", line 846, in source_to_code
  File "<frozen importlib._bootstrap>", line 219, in _call_with_frames_removed
  File "C:\Users\romanpc\dev\env\env\bookmarks\bookmarks\account\urls.py", line 15
    path('reset/done/', auth_views.PasswordResetCompleteView.as-view(), name='password_reset_complete'),
                                                             ^
SyntaxError: invalid syntax
C:\Users\romanpc\Dev\env\env\bookmarks\bookmarks\account\urls.py changed, reloading.
Watching for file changes with StatReloader
Performing system checks...

System check identified no issues (0 silenced).
October 18, 2020 - 16:45:16
Django version 3.1.2, using settings 'bookmarks.settings'
Starting development server at http://127.0.0.1:8000/
Quit the server with CTRL-BREAK.
(bookmarks) PS C:\Users\romanpc\dev\env\env\bookmarks\bookmarks> python manage.py runserver
Watching for file changes with StatReloader
Performing system checks...

System check identified no issues (0 silenced).
October 18, 2020 - 16:56:40
Django version 3.1.2, using settings 'bookmarks.settings'
Starting development server at http://127.0.0.1:8000/
Quit the server with CTRL-BREAK.
[18/Oct/2020 16:56:50] "GET /account/login HTTP/1.1" 301 0
Internal Server Error: /account/login/
Traceback (most recent call last):
  File "C:\Users\romanpc\dev\env\env\bookmarks\lib\site-packages\django\urls\base.py", line 72, in reverse
    extra, resolver = resolver.namespace_dict[ns]
KeyError: 'images'

During handling of the above exception, another exception occurred:

Traceback (most recent call last):
  File "C:\Users\romanpc\dev\env\env\bookmarks\lib\site-packages\django\core\handlers\exception.py", line 47, in inner
    response = get_response(request)
  File "C:\Users\romanpc\dev\env\env\bookmarks\lib\site-packages\django\core\handlers\base.py", line 202, in _get_response
    response = response.render()
  File "C:\Users\romanpc\dev\env\env\bookmarks\lib\site-packages\django\template\response.py", line 105, in render
    self.content = self.rendered_content
  File "C:\Users\romanpc\dev\env\env\bookmarks\lib\site-packages\django\template\response.py", line 83, in rendered_content
    return template.render(context, self._request)
  File "C:\Users\romanpc\dev\env\env\bookmarks\lib\site-packages\django\template\backends\django.py", line 61, in render
    return self.template.render(context)
  File "C:\Users\romanpc\dev\env\env\bookmarks\lib\site-packages\django\template\base.py", line 170, in render
    return self._render(context)
  File "C:\Users\romanpc\dev\env\env\bookmarks\lib\site-packages\django\template\base.py", line 162, in _render
    return self.nodelist.render(context)
  File "C:\Users\romanpc\dev\env\env\bookmarks\lib\site-packages\django\template\base.py", line 938, in render
    bit = node.render_annotated(context)
  File "C:\Users\romanpc\dev\env\env\bookmarks\lib\site-packages\django\template\base.py", line 905, in render_annotated
    return self.render(context)
  File "C:\Users\romanpc\dev\env\env\bookmarks\lib\site-packages\django\template\loader_tags.py", line 150, in render
    return compiled_parent._render(context)
  File "C:\Users\romanpc\dev\env\env\bookmarks\lib\site-packages\django\template\base.py", line 162, in _render
    return self.nodelist.render(context)
  File "C:\Users\romanpc\dev\env\env\bookmarks\lib\site-packages\django\template\base.py", line 938, in render
    bit = node.render_annotated(context)
  File "C:\Users\romanpc\dev\env\env\bookmarks\lib\site-packages\django\template\base.py", line 905, in render_annotated
    return self.render(context)
  File "C:\Users\romanpc\dev\env\env\bookmarks\lib\site-packages\django\template\defaulttags.py", line 312, in render
    return nodelist.render(context)
  File "C:\Users\romanpc\dev\env\env\bookmarks\lib\site-packages\django\template\base.py", line 938, in render
    bit = node.render_annotated(context)
  File "C:\Users\romanpc\dev\env\env\bookmarks\lib\site-packages\django\template\base.py", line 905, in render_annotated
    return self.render(context)
  File "C:\Users\romanpc\dev\env\env\bookmarks\lib\site-packages\django\template\defaulttags.py", line 446, in render
    url = reverse(view_name, args=args, kwargs=kwargs, current_app=current_app)
  File "C:\Users\romanpc\dev\env\env\bookmarks\lib\site-packages\django\urls\base.py", line 83, in reverse
    raise NoReverseMatch("%s is not a registered namespace" % key)
django.urls.exceptions.NoReverseMatch: 'images' is not a registered namespace
[18/Oct/2020 16:56:50] "GET /account/login/ HTTP/1.1" 500 146728
Internal Server Error: /account/
Traceback (most recent call last):
  File "C:\Users\romanpc\dev\env\env\bookmarks\lib\site-packages\django\core\handlers\exception.py", line 47, in inner
    response = get_response(request)
  File "C:\Users\romanpc\dev\env\env\bookmarks\lib\site-packages\django\core\handlers\base.py", line 179, in _get_response
    response = wrapped_callback(request, *callback_args, **callback_kwargs)
  File "C:\Users\romanpc\dev\env\env\bookmarks\lib\site-packages\django\contrib\auth\decorators.py", line 21, in _wrapped_view
    return view_func(request, *args, **kwargs)
  File "C:\Users\romanpc\dev\env\env\bookmarks\bookmarks\account\views.py", line 40, in dashboard
    'actions': actions, })
NameError: name 'actions' is not defined
[18/Oct/2020 16:56:55] "GET /account/ HTTP/1.1" 500 66594
C:\Users\romanpc\Dev\env\env\bookmarks\bookmarks\account\views.py changed, reloading.
Watching for file changes with StatReloader
Performing system checks...

Exception in thread django-main-thread:
Traceback (most recent call last):
  File "C:\Python38\lib\threading.py", line 932, in _bootstrap_inner
    self.run()
  File "C:\Python38\lib\threading.py", line 870, in run
    self._target(*self._args, **self._kwargs)
  File "C:\Users\romanpc\dev\env\env\bookmarks\lib\site-packages\django\utils\autoreload.py", line 53, in wrapper
    fn(*args, **kwargs)
  File "C:\Users\romanpc\dev\env\env\bookmarks\lib\site-packages\django\core\management\commands\runserver.py", line 118, in inner_run
    self.check(display_num_errors=True)
  File "C:\Users\romanpc\dev\env\env\bookmarks\lib\site-packages\django\core\management\base.py", line 392, in check
    all_issues = checks.run_checks(
  File "C:\Users\romanpc\dev\env\env\bookmarks\lib\site-packages\django\core\checks\registry.py", line 70, in run_checks
    new_errors = check(app_configs=app_configs, databases=databases)
  File "C:\Users\romanpc\dev\env\env\bookmarks\lib\site-packages\django\core\checks\urls.py", line 40, in check_url_namespaces_unique
    all_namespaces = _load_all_namespaces(resolver)
  File "C:\Users\romanpc\dev\env\env\bookmarks\lib\site-packages\django\core\checks\urls.py", line 57, in _load_all_namespaces
    url_patterns = getattr(resolver, 'url_patterns', [])
  File "C:\Users\romanpc\dev\env\env\bookmarks\lib\site-packages\django\utils\functional.py", line 48, in __get__
    res = instance.__dict__[self.name] = self.func(instance)
  File "C:\Users\romanpc\dev\env\env\bookmarks\lib\site-packages\django\urls\resolvers.py", line 589, in url_patterns
    patterns = getattr(self.urlconf_module, "urlpatterns", self.urlconf_module)
  File "C:\Users\romanpc\dev\env\env\bookmarks\lib\site-packages\django\utils\functional.py", line 48, in __get__
    res = instance.__dict__[self.name] = self.func(instance)
  File "C:\Users\romanpc\dev\env\env\bookmarks\lib\site-packages\django\urls\resolvers.py", line 582, in urlconf_module
    return import_module(self.urlconf_name)
  File "C:\Python38\lib\importlib\__init__.py", line 127, in import_module
    return _bootstrap._gcd_import(name[level:], package, level)
  File "<frozen importlib._bootstrap>", line 1014, in _gcd_import
  File "<frozen importlib._bootstrap>", line 991, in _find_and_load
  File "<frozen importlib._bootstrap>", line 975, in _find_and_load_unlocked
  File "<frozen importlib._bootstrap>", line 671, in _load_unlocked
  File "<frozen importlib._bootstrap_external>", line 783, in exec_module
  File "<frozen importlib._bootstrap>", line 219, in _call_with_frames_removed
  File "C:\Users\romanpc\dev\env\env\bookmarks\bookmarks\bookmarks\urls.py", line 24, in <module>
    path('account/', include('account.urls')),
  File "C:\Users\romanpc\dev\env\env\bookmarks\lib\site-packages\django\urls\conf.py", line 34, in include
    urlconf_module = import_module(urlconf_module)
  File "C:\Python38\lib\importlib\__init__.py", line 127, in import_module
    return _bootstrap._gcd_import(name[level:], package, level)
  File "<frozen importlib._bootstrap>", line 1014, in _gcd_import
  File "<frozen importlib._bootstrap>", line 991, in _find_and_load
  File "<frozen importlib._bootstrap>", line 975, in _find_and_load_unlocked
  File "<frozen importlib._bootstrap>", line 671, in _load_unlocked
  File "<frozen importlib._bootstrap_external>", line 783, in exec_module
  File "<frozen importlib._bootstrap>", line 219, in _call_with_frames_removed
  File "C:\Users\romanpc\dev\env\env\bookmarks\bookmarks\account\urls.py", line 3, in <module>
    from . import views
  File "C:\Users\romanpc\dev\env\env\bookmarks\bookmarks\account\views.py", line 39
    #    'actions': actions, })
                              ^
SyntaxError: unexpected EOF while parsing
(bookmarks) PS C:\Users\romanpc\dev\env\env\bookmarks\bookmarks> python manage.py runserver
Watching for file changes with StatReloader
Performing system checks...

Exception in thread django-main-thread:
Traceback (most recent call last):
  File "C:\Python38\lib\threading.py", line 932, in _bootstrap_inner
    self.run()
  File "C:\Python38\lib\threading.py", line 870, in run
    self._target(*self._args, **self._kwargs)
  File "C:\Users\romanpc\dev\env\env\bookmarks\lib\site-packages\django\utils\autoreload.py", line 53, in wrapper
    fn(*args, **kwargs)
  File "C:\Users\romanpc\dev\env\env\bookmarks\lib\site-packages\django\core\management\commands\runserver.py", line 118, in inner_run
    self.check(display_num_errors=True)
  File "C:\Users\romanpc\dev\env\env\bookmarks\lib\site-packages\django\core\management\base.py", line 392, in check
    all_issues = checks.run_checks(
  File "C:\Users\romanpc\dev\env\env\bookmarks\lib\site-packages\django\core\checks\registry.py", line 70, in run_checks
    new_errors = check(app_configs=app_configs, databases=databases)
  File "C:\Users\romanpc\dev\env\env\bookmarks\lib\site-packages\django\core\checks\urls.py", line 40, in check_url_namespaces_unique
    all_namespaces = _load_all_namespaces(resolver)
  File "C:\Users\romanpc\dev\env\env\bookmarks\lib\site-packages\django\core\checks\urls.py", line 57, in _load_all_namespaces
    url_patterns = getattr(resolver, 'url_patterns', [])
  File "C:\Users\romanpc\dev\env\env\bookmarks\lib\site-packages\django\utils\functional.py", line 48, in __get__
    res = instance.__dict__[self.name] = self.func(instance)
  File "C:\Users\romanpc\dev\env\env\bookmarks\lib\site-packages\django\urls\resolvers.py", line 589, in url_patterns
    patterns = getattr(self.urlconf_module, "urlpatterns", self.urlconf_module)
  File "C:\Users\romanpc\dev\env\env\bookmarks\lib\site-packages\django\utils\functional.py", line 48, in __get__
    res = instance.__dict__[self.name] = self.func(instance)
  File "C:\Users\romanpc\dev\env\env\bookmarks\lib\site-packages\django\urls\resolvers.py", line 582, in urlconf_module
    return import_module(self.urlconf_name)
  File "C:\Python38\lib\importlib\__init__.py", line 127, in import_module
    return _bootstrap._gcd_import(name[level:], package, level)
  File "<frozen importlib._bootstrap>", line 1014, in _gcd_import
  File "<frozen importlib._bootstrap>", line 991, in _find_and_load
  File "<frozen importlib._bootstrap>", line 975, in _find_and_load_unlocked
  File "<frozen importlib._bootstrap>", line 671, in _load_unlocked
  File "<frozen importlib._bootstrap_external>", line 783, in exec_module
  File "<frozen importlib._bootstrap>", line 219, in _call_with_frames_removed
  File "C:\Users\romanpc\dev\env\env\bookmarks\bookmarks\bookmarks\urls.py", line 24, in <module>
    path('account/', include('account.urls')),
  File "C:\Users\romanpc\dev\env\env\bookmarks\lib\site-packages\django\urls\conf.py", line 34, in include
    urlconf_module = import_module(urlconf_module)
  File "C:\Python38\lib\importlib\__init__.py", line 127, in import_module
    return _bootstrap._gcd_import(name[level:], package, level)
  File "<frozen importlib._bootstrap>", line 1014, in _gcd_import
  File "<frozen importlib._bootstrap>", line 991, in _find_and_load
  File "<frozen importlib._bootstrap>", line 975, in _find_and_load_unlocked
  File "<frozen importlib._bootstrap>", line 671, in _load_unlocked
  File "<frozen importlib._bootstrap_external>", line 783, in exec_module
  File "<frozen importlib._bootstrap>", line 219, in _call_with_frames_removed
  File "C:\Users\romanpc\dev\env\env\bookmarks\bookmarks\account\urls.py", line 3, in <module>
    from . import views
  File "C:\Users\romanpc\dev\env\env\bookmarks\bookmarks\account\views.py", line 39
    #    'actions': actions, })
                              ^
SyntaxError: unexpected EOF while parsing
C:\Users\romanpc\Dev\env\env\bookmarks\bookmarks\account\views.py changed, reloading.
Watching for file changes with StatReloader
Performing system checks...

System check identified no issues (0 silenced).
October 18, 2020 - 16:59:33
Django version 3.1.2, using settings 'bookmarks.settings'
Starting development server at http://127.0.0.1:8000/
Quit the server with CTRL-BREAK.
Internal Server Error: /account/
Traceback (most recent call last):
  File "C:\Users\romanpc\dev\env\env\bookmarks\lib\site-packages\django\urls\base.py", line 72, in reverse
    extra, resolver = resolver.namespace_dict[ns]
KeyError: 'images'

During handling of the above exception, another exception occurred:

Traceback (most recent call last):
  File "C:\Users\romanpc\dev\env\env\bookmarks\lib\site-packages\django\core\handlers\exception.py", line 47, in inner
    response = get_response(request)
  File "C:\Users\romanpc\dev\env\env\bookmarks\lib\site-packages\django\core\handlers\base.py", line 179, in _get_response
    response = wrapped_callback(request, *callback_args, **callback_kwargs)
  File "C:\Users\romanpc\dev\env\env\bookmarks\lib\site-packages\django\contrib\auth\decorators.py", line 21, in _wrapped_view
    return view_func(request, *args, **kwargs)
  File "C:\Users\romanpc\dev\env\env\bookmarks\bookmarks\account\views.py", line 36, in dashboard
    return render(request,
  File "C:\Users\romanpc\dev\env\env\bookmarks\lib\site-packages\django\shortcuts.py", line 19, in render
    content = loader.render_to_string(template_name, context, request, using=using)
  File "C:\Users\romanpc\dev\env\env\bookmarks\lib\site-packages\django\template\loader.py", line 62, in render_to_string
    return template.render(context, request)
  File "C:\Users\romanpc\dev\env\env\bookmarks\lib\site-packages\django\template\backends\django.py", line 61, in render
    return self.template.render(context)
  File "C:\Users\romanpc\dev\env\env\bookmarks\lib\site-packages\django\template\base.py", line 170, in render
    return self._render(context)
  File "C:\Users\romanpc\dev\env\env\bookmarks\lib\site-packages\django\template\base.py", line 162, in _render
    return self.nodelist.render(context)
  File "C:\Users\romanpc\dev\env\env\bookmarks\lib\site-packages\django\template\base.py", line 938, in render
    bit = node.render_annotated(context)
  File "C:\Users\romanpc\dev\env\env\bookmarks\lib\site-packages\django\template\base.py", line 905, in render_annotated
    return self.render(context)
  File "C:\Users\romanpc\dev\env\env\bookmarks\lib\site-packages\django\template\loader_tags.py", line 150, in render
    return compiled_parent._render(context)
  File "C:\Users\romanpc\dev\env\env\bookmarks\lib\site-packages\django\template\base.py", line 162, in _render
    return self.nodelist.render(context)
  File "C:\Users\romanpc\dev\env\env\bookmarks\lib\site-packages\django\template\base.py", line 938, in render
    bit = node.render_annotated(context)
  File "C:\Users\romanpc\dev\env\env\bookmarks\lib\site-packages\django\template\base.py", line 905, in render_annotated
    return self.render(context)
  File "C:\Users\romanpc\dev\env\env\bookmarks\lib\site-packages\django\template\defaulttags.py", line 312, in render
    return nodelist.render(context)
  File "C:\Users\romanpc\dev\env\env\bookmarks\lib\site-packages\django\template\base.py", line 938, in render
    bit = node.render_annotated(context)
  File "C:\Users\romanpc\dev\env\env\bookmarks\lib\site-packages\django\template\base.py", line 905, in render_annotated
    return self.render(context)
  File "C:\Users\romanpc\dev\env\env\bookmarks\lib\site-packages\django\template\defaulttags.py", line 446, in render
    url = reverse(view_name, args=args, kwargs=kwargs, current_app=current_app)
  File "C:\Users\romanpc\dev\env\env\bookmarks\lib\site-packages\django\urls\base.py", line 83, in reverse
    raise NoReverseMatch("%s is not a registered namespace" % key)
django.urls.exceptions.NoReverseMatch: 'images' is not a registered namespace
[18/Oct/2020 16:59:37] "GET /account/ HTTP/1.1" 500 151077
Internal Server Error: /account/
Traceback (most recent call last):
  File "C:\Users\romanpc\dev\env\env\bookmarks\lib\site-packages\django\urls\base.py", line 72, in reverse
    extra, resolver = resolver.namespace_dict[ns]
KeyError: 'images'

During handling of the above exception, another exception occurred:

Traceback (most recent call last):
  File "C:\Users\romanpc\dev\env\env\bookmarks\lib\site-packages\django\core\handlers\exception.py", line 47, in inner
    response = get_response(request)
  File "C:\Users\romanpc\dev\env\env\bookmarks\lib\site-packages\django\core\handlers\base.py", line 179, in _get_response
    response = wrapped_callback(request, *callback_args, **callback_kwargs)
  File "C:\Users\romanpc\dev\env\env\bookmarks\lib\site-packages\django\contrib\auth\decorators.py", line 21, in _wrapped_view
    return view_func(request, *args, **kwargs)
  File "C:\Users\romanpc\dev\env\env\bookmarks\bookmarks\account\views.py", line 36, in dashboard
    return render(request,
  File "C:\Users\romanpc\dev\env\env\bookmarks\lib\site-packages\django\shortcuts.py", line 19, in render
    content = loader.render_to_string(template_name, context, request, using=using)
  File "C:\Users\romanpc\dev\env\env\bookmarks\lib\site-packages\django\template\loader.py", line 62, in render_to_string
    return template.render(context, request)
  File "C:\Users\romanpc\dev\env\env\bookmarks\lib\site-packages\django\template\backends\django.py", line 61, in render
    return self.template.render(context)
  File "C:\Users\romanpc\dev\env\env\bookmarks\lib\site-packages\django\template\base.py", line 170, in render
    return self._render(context)
  File "C:\Users\romanpc\dev\env\env\bookmarks\lib\site-packages\django\template\base.py", line 162, in _render
    return self.nodelist.render(context)
  File "C:\Users\romanpc\dev\env\env\bookmarks\lib\site-packages\django\template\base.py", line 938, in render
    bit = node.render_annotated(context)
  File "C:\Users\romanpc\dev\env\env\bookmarks\lib\site-packages\django\template\base.py", line 905, in render_annotated
    return self.render(context)
  File "C:\Users\romanpc\dev\env\env\bookmarks\lib\site-packages\django\template\loader_tags.py", line 150, in render
    return compiled_parent._render(context)
  File "C:\Users\romanpc\dev\env\env\bookmarks\lib\site-packages\django\template\base.py", line 162, in _render
    return self.nodelist.render(context)
  File "C:\Users\romanpc\dev\env\env\bookmarks\lib\site-packages\django\template\base.py", line 938, in render
    bit = node.render_annotated(context)
  File "C:\Users\romanpc\dev\env\env\bookmarks\lib\site-packages\django\template\base.py", line 905, in render_annotated
    return self.render(context)
  File "C:\Users\romanpc\dev\env\env\bookmarks\lib\site-packages\django\template\defaulttags.py", line 312, in render
    return nodelist.render(context)
  File "C:\Users\romanpc\dev\env\env\bookmarks\lib\site-packages\django\template\base.py", line 938, in render
    bit = node.render_annotated(context)
  File "C:\Users\romanpc\dev\env\env\bookmarks\lib\site-packages\django\template\base.py", line 905, in render_annotated
    return self.render(context)
  File "C:\Users\romanpc\dev\env\env\bookmarks\lib\site-packages\django\template\defaulttags.py", line 446, in render
    url = reverse(view_name, args=args, kwargs=kwargs, current_app=current_app)
  File "C:\Users\romanpc\dev\env\env\bookmarks\lib\site-packages\django\urls\base.py", line 83, in reverse
    raise NoReverseMatch("%s is not a registered namespace" % key)
django.urls.exceptions.NoReverseMatch: 'images' is not a registered namespace
[18/Oct/2020 16:59:38] "GET /account/ HTTP/1.1" 500 151077
Internal Server Error: /account/login/
Traceback (most recent call last):
  File "C:\Users\romanpc\dev\env\env\bookmarks\lib\site-packages\django\urls\base.py", line 72, in reverse
    extra, resolver = resolver.namespace_dict[ns]
KeyError: 'images'

During handling of the above exception, another exception occurred:

Traceback (most recent call last):
  File "C:\Users\romanpc\dev\env\env\bookmarks\lib\site-packages\django\core\handlers\exception.py", line 47, in inner
    response = get_response(request)
  File "C:\Users\romanpc\dev\env\env\bookmarks\lib\site-packages\django\core\handlers\base.py", line 202, in _get_response
    response = response.render()
  File "C:\Users\romanpc\dev\env\env\bookmarks\lib\site-packages\django\template\response.py", line 105, in render
    self.content = self.rendered_content
  File "C:\Users\romanpc\dev\env\env\bookmarks\lib\site-packages\django\template\response.py", line 83, in rendered_content
    return template.render(context, self._request)
  File "C:\Users\romanpc\dev\env\env\bookmarks\lib\site-packages\django\template\backends\django.py", line 61, in render
    return self.template.render(context)
  File "C:\Users\romanpc\dev\env\env\bookmarks\lib\site-packages\django\template\base.py", line 170, in render
    return self._render(context)
  File "C:\Users\romanpc\dev\env\env\bookmarks\lib\site-packages\django\template\base.py", line 162, in _render
    return self.nodelist.render(context)
  File "C:\Users\romanpc\dev\env\env\bookmarks\lib\site-packages\django\template\base.py", line 938, in render
    bit = node.render_annotated(context)
  File "C:\Users\romanpc\dev\env\env\bookmarks\lib\site-packages\django\template\base.py", line 905, in render_annotated
    return self.render(context)
  File "C:\Users\romanpc\dev\env\env\bookmarks\lib\site-packages\django\template\loader_tags.py", line 150, in render
    return compiled_parent._render(context)
  File "C:\Users\romanpc\dev\env\env\bookmarks\lib\site-packages\django\template\base.py", line 162, in _render
    return self.nodelist.render(context)
  File "C:\Users\romanpc\dev\env\env\bookmarks\lib\site-packages\django\template\base.py", line 938, in render
    bit = node.render_annotated(context)
  File "C:\Users\romanpc\dev\env\env\bookmarks\lib\site-packages\django\template\base.py", line 905, in render_annotated
    return self.render(context)
  File "C:\Users\romanpc\dev\env\env\bookmarks\lib\site-packages\django\template\defaulttags.py", line 312, in render
    return nodelist.render(context)
  File "C:\Users\romanpc\dev\env\env\bookmarks\lib\site-packages\django\template\base.py", line 938, in render
    bit = node.render_annotated(context)
  File "C:\Users\romanpc\dev\env\env\bookmarks\lib\site-packages\django\template\base.py", line 905, in render_annotated
    return self.render(context)
  File "C:\Users\romanpc\dev\env\env\bookmarks\lib\site-packages\django\template\defaulttags.py", line 446, in render
    url = reverse(view_name, args=args, kwargs=kwargs, current_app=current_app)
  File "C:\Users\romanpc\dev\env\env\bookmarks\lib\site-packages\django\urls\base.py", line 83, in reverse
    raise NoReverseMatch("%s is not a registered namespace" % key)
django.urls.exceptions.NoReverseMatch: 'images' is not a registered namespace
[18/Oct/2020 17:00:11] "GET /account/login/ HTTP/1.1" 500 146728
C:\Users\romanpc\Dev\env\env\bookmarks\bookmarks\bookmarks\settings.py changed, reloading.
Watching for file changes with StatReloader
Performing system checks...

System check identified no issues (0 silenced).
October 18, 2020 - 17:02:59
Django version 3.1.2, using settings 'bookmarks.settings'
Starting development server at http://127.0.0.1:8000/
Quit the server with CTRL-BREAK.
C:\Users\romanpc\Dev\env\env\bookmarks\bookmarks\account\urls.py changed, reloading.
Watching for file changes with StatReloader
Performing system checks...

Exception in thread django-main-thread:
Traceback (most recent call last):
  File "C:\Python38\lib\threading.py", line 932, in _bootstrap_inner
    self.run()
  File "C:\Python38\lib\threading.py", line 870, in run
    self._target(*self._args, **self._kwargs)
  File "C:\Users\romanpc\dev\env\env\bookmarks\lib\site-packages\django\utils\autoreload.py", line 53, in wrapper
    fn(*args, **kwargs)
  File "C:\Users\romanpc\dev\env\env\bookmarks\lib\site-packages\django\core\management\commands\runserver.py", line 118, in inner_run
    self.check(display_num_errors=True)
  File "C:\Users\romanpc\dev\env\env\bookmarks\lib\site-packages\django\core\management\base.py", line 392, in check
    all_issues = checks.run_checks(
  File "C:\Users\romanpc\dev\env\env\bookmarks\lib\site-packages\django\core\checks\registry.py", line 70, in run_checks
    new_errors = check(app_configs=app_configs, databases=databases)
  File "C:\Users\romanpc\dev\env\env\bookmarks\lib\site-packages\django\core\checks\urls.py", line 40, in check_url_namespaces_unique
    all_namespaces = _load_all_namespaces(resolver)
  File "C:\Users\romanpc\dev\env\env\bookmarks\lib\site-packages\django\core\checks\urls.py", line 57, in _load_all_namespaces
    url_patterns = getattr(resolver, 'url_patterns', [])
  File "C:\Users\romanpc\dev\env\env\bookmarks\lib\site-packages\django\utils\functional.py", line 48, in __get__
    res = instance.__dict__[self.name] = self.func(instance)
  File "C:\Users\romanpc\dev\env\env\bookmarks\lib\site-packages\django\urls\resolvers.py", line 589, in url_patterns
    patterns = getattr(self.urlconf_module, "urlpatterns", self.urlconf_module)
  File "C:\Users\romanpc\dev\env\env\bookmarks\lib\site-packages\django\utils\functional.py", line 48, in __get__
    res = instance.__dict__[self.name] = self.func(instance)
  File "C:\Users\romanpc\dev\env\env\bookmarks\lib\site-packages\django\urls\resolvers.py", line 582, in urlconf_module
    return import_module(self.urlconf_name)
  File "C:\Python38\lib\importlib\__init__.py", line 127, in import_module
    return _bootstrap._gcd_import(name[level:], package, level)
  File "<frozen importlib._bootstrap>", line 1014, in _gcd_import
  File "<frozen importlib._bootstrap>", line 991, in _find_and_load
  File "<frozen importlib._bootstrap>", line 975, in _find_and_load_unlocked
  File "<frozen importlib._bootstrap>", line 671, in _load_unlocked
  File "<frozen importlib._bootstrap_external>", line 783, in exec_module
  File "<frozen importlib._bootstrap>", line 219, in _call_with_frames_removed
  File "C:\Users\romanpc\dev\env\env\bookmarks\bookmarks\bookmarks\urls.py", line 24, in <module>
    path('account/', include('account.urls')),
  File "C:\Users\romanpc\dev\env\env\bookmarks\lib\site-packages\django\urls\conf.py", line 34, in include
    urlconf_module = import_module(urlconf_module)
  File "C:\Python38\lib\importlib\__init__.py", line 127, in import_module
    return _bootstrap._gcd_import(name[level:], package, level)
  File "<frozen importlib._bootstrap>", line 1014, in _gcd_import
  File "<frozen importlib._bootstrap>", line 991, in _find_and_load
  File "<frozen importlib._bootstrap>", line 975, in _find_and_load_unlocked
  File "<frozen importlib._bootstrap>", line 671, in _load_unlocked
  File "<frozen importlib._bootstrap_external>", line 783, in exec_module
  File "<frozen importlib._bootstrap>", line 219, in _call_with_frames_removed
  File "C:\Users\romanpc\dev\env\env\bookmarks\bookmarks\account\urls.py", line 16, in <module>
    path('', include('django.contrib.auth.urls')),
NameError: name 'include' is not defined
(bookmarks) PS C:\Users\romanpc\dev\env\env\bookmarks\bookmarks> python manage.py runserver
Watching for file changes with StatReloader
Performing system checks...

Exception in thread django-main-thread:
Traceback (most recent call last):
  File "C:\Python38\lib\threading.py", line 932, in _bootstrap_inner
    self.run()
  File "C:\Python38\lib\threading.py", line 870, in run
    self._target(*self._args, **self._kwargs)
  File "C:\Users\romanpc\dev\env\env\bookmarks\lib\site-packages\django\utils\autoreload.py", line 53, in wrapper
    fn(*args, **kwargs)
  File "C:\Users\romanpc\dev\env\env\bookmarks\lib\site-packages\django\core\management\commands\runserver.py", line 118, in inner_run
    self.check(display_num_errors=True)
  File "C:\Users\romanpc\dev\env\env\bookmarks\lib\site-packages\django\core\management\base.py", line 392, in check
    all_issues = checks.run_checks(
  File "C:\Users\romanpc\dev\env\env\bookmarks\lib\site-packages\django\core\checks\registry.py", line 70, in run_checks
    new_errors = check(app_configs=app_configs, databases=databases)
  File "C:\Users\romanpc\dev\env\env\bookmarks\lib\site-packages\django\core\checks\urls.py", line 40, in check_url_namespaces_unique
    all_namespaces = _load_all_namespaces(resolver)
  File "C:\Users\romanpc\dev\env\env\bookmarks\lib\site-packages\django\core\checks\urls.py", line 57, in _load_all_namespaces
    url_patterns = getattr(resolver, 'url_patterns', [])
  File "C:\Users\romanpc\dev\env\env\bookmarks\lib\site-packages\django\utils\functional.py", line 48, in __get__
    res = instance.__dict__[self.name] = self.func(instance)
  File "C:\Users\romanpc\dev\env\env\bookmarks\lib\site-packages\django\urls\resolvers.py", line 589, in url_patterns
    patterns = getattr(self.urlconf_module, "urlpatterns", self.urlconf_module)
  File "C:\Users\romanpc\dev\env\env\bookmarks\lib\site-packages\django\utils\functional.py", line 48, in __get__
    res = instance.__dict__[self.name] = self.func(instance)
  File "C:\Users\romanpc\dev\env\env\bookmarks\lib\site-packages\django\urls\resolvers.py", line 582, in urlconf_module
    return import_module(self.urlconf_name)
  File "C:\Python38\lib\importlib\__init__.py", line 127, in import_module
    return _bootstrap._gcd_import(name[level:], package, level)
  File "<frozen importlib._bootstrap>", line 1014, in _gcd_import
  File "<frozen importlib._bootstrap>", line 991, in _find_and_load
  File "<frozen importlib._bootstrap>", line 975, in _find_and_load_unlocked
  File "<frozen importlib._bootstrap>", line 671, in _load_unlocked
  File "<frozen importlib._bootstrap_external>", line 783, in exec_module
  File "<frozen importlib._bootstrap>", line 219, in _call_with_frames_removed
  File "C:\Users\romanpc\dev\env\env\bookmarks\bookmarks\bookmarks\urls.py", line 24, in <module>
    path('account/', include('account.urls')),
  File "C:\Users\romanpc\dev\env\env\bookmarks\lib\site-packages\django\urls\conf.py", line 34, in include
    urlconf_module = import_module(urlconf_module)
  File "C:\Python38\lib\importlib\__init__.py", line 127, in import_module
    return _bootstrap._gcd_import(name[level:], package, level)
  File "<frozen importlib._bootstrap>", line 1014, in _gcd_import
  File "<frozen importlib._bootstrap>", line 991, in _find_and_load
  File "<frozen importlib._bootstrap>", line 975, in _find_and_load_unlocked
  File "<frozen importlib._bootstrap>", line 671, in _load_unlocked
  File "<frozen importlib._bootstrap_external>", line 783, in exec_module
  File "<frozen importlib._bootstrap>", line 219, in _call_with_frames_removed
  File "C:\Users\romanpc\dev\env\env\bookmarks\bookmarks\account\urls.py", line 16, in <module>
    path('', include('django.contrib.auth.urls')),
NameError: name 'include' is not defined
C:\Users\romanpc\Dev\env\env\bookmarks\bookmarks\account\urls.py changed, reloading.
Watching for file changes with StatReloader
Performing system checks...

Exception in thread django-main-thread:
Traceback (most recent call last):
  File "C:\Python38\lib\threading.py", line 932, in _bootstrap_inner
    self.run()
  File "C:\Python38\lib\threading.py", line 870, in run
    self._target(*self._args, **self._kwargs)
  File "C:\Users\romanpc\dev\env\env\bookmarks\lib\site-packages\django\utils\autoreload.py", line 53, in wrapper
    fn(*args, **kwargs)
  File "C:\Users\romanpc\dev\env\env\bookmarks\lib\site-packages\django\core\management\commands\runserver.py", line 118, in inner_run
    self.check(display_num_errors=True)
  File "C:\Users\romanpc\dev\env\env\bookmarks\lib\site-packages\django\core\management\base.py", line 392, in check
    all_issues = checks.run_checks(
  File "C:\Users\romanpc\dev\env\env\bookmarks\lib\site-packages\django\core\checks\registry.py", line 70, in run_checks
    new_errors = check(app_configs=app_configs, databases=databases)
  File "C:\Users\romanpc\dev\env\env\bookmarks\lib\site-packages\django\core\checks\urls.py", line 40, in check_url_namespaces_unique
    all_namespaces = _load_all_namespaces(resolver)
  File "C:\Users\romanpc\dev\env\env\bookmarks\lib\site-packages\django\core\checks\urls.py", line 57, in _load_all_namespaces
    url_patterns = getattr(resolver, 'url_patterns', [])
  File "C:\Users\romanpc\dev\env\env\bookmarks\lib\site-packages\django\utils\functional.py", line 48, in __get__
    res = instance.__dict__[self.name] = self.func(instance)
  File "C:\Users\romanpc\dev\env\env\bookmarks\lib\site-packages\django\urls\resolvers.py", line 589, in url_patterns
    patterns = getattr(self.urlconf_module, "urlpatterns", self.urlconf_module)
  File "C:\Users\romanpc\dev\env\env\bookmarks\lib\site-packages\django\utils\functional.py", line 48, in __get__
    res = instance.__dict__[self.name] = self.func(instance)
  File "C:\Users\romanpc\dev\env\env\bookmarks\lib\site-packages\django\urls\resolvers.py", line 582, in urlconf_module
    return import_module(self.urlconf_name)
  File "C:\Python38\lib\importlib\__init__.py", line 127, in import_module
    return _bootstrap._gcd_import(name[level:], package, level)
  File "<frozen importlib._bootstrap>", line 1014, in _gcd_import
  File "<frozen importlib._bootstrap>", line 991, in _find_and_load
  File "<frozen importlib._bootstrap>", line 975, in _find_and_load_unlocked
  File "<frozen importlib._bootstrap>", line 671, in _load_unlocked
  File "<frozen importlib._bootstrap_external>", line 783, in exec_module
  File "<frozen importlib._bootstrap>", line 219, in _call_with_frames_removed
  File "C:\Users\romanpc\dev\env\env\bookmarks\bookmarks\bookmarks\urls.py", line 24, in <module>
    path('account/', include('account.urls')),
  File "C:\Users\romanpc\dev\env\env\bookmarks\lib\site-packages\django\urls\conf.py", line 34, in include
    urlconf_module = import_module(urlconf_module)
  File "C:\Python38\lib\importlib\__init__.py", line 127, in import_module
    return _bootstrap._gcd_import(name[level:], package, level)
  File "<frozen importlib._bootstrap>", line 1014, in _gcd_import
  File "<frozen importlib._bootstrap>", line 991, in _find_and_load
  File "<frozen importlib._bootstrap>", line 975, in _find_and_load_unlocked
  File "<frozen importlib._bootstrap>", line 671, in _load_unlocked
  File "<frozen importlib._bootstrap_external>", line 783, in exec_module
  File "<frozen importlib._bootstrap>", line 219, in _call_with_frames_removed
  File "C:\Users\romanpc\dev\env\env\bookmarks\bookmarks\account\urls.py", line 16, in <module>
    path('', include('django.contrib.auth.urls')),
NameError: name 'include' is not defined
(bookmarks) PS C:\Users\romanpc\dev\env\env\bookmarks\bookmarks> python manage.py runserver
Watching for file changes with StatReloader
Performing system checks...

Exception in thread django-main-thread:
Traceback (most recent call last):
  File "C:\Python38\lib\threading.py", line 932, in _bootstrap_inner
    self.run()
  File "C:\Python38\lib\threading.py", line 870, in run
    self._target(*self._args, **self._kwargs)
  File "C:\Users\romanpc\dev\env\env\bookmarks\lib\site-packages\django\utils\autoreload.py", line 53, in wrapper
    fn(*args, **kwargs)
  File "C:\Users\romanpc\dev\env\env\bookmarks\lib\site-packages\django\core\management\commands\runserver.py", line 118, in inner_run
    self.check(display_num_errors=True)
  File "C:\Users\romanpc\dev\env\env\bookmarks\lib\site-packages\django\core\management\base.py", line 392, in check
    all_issues = checks.run_checks(
  File "C:\Users\romanpc\dev\env\env\bookmarks\lib\site-packages\django\core\checks\registry.py", line 70, in run_checks
    new_errors = check(app_configs=app_configs, databases=databases)
  File "C:\Users\romanpc\dev\env\env\bookmarks\lib\site-packages\django\core\checks\urls.py", line 40, in check_url_namespaces_unique
    all_namespaces = _load_all_namespaces(resolver)
  File "C:\Users\romanpc\dev\env\env\bookmarks\lib\site-packages\django\core\checks\urls.py", line 57, in _load_all_namespaces
    url_patterns = getattr(resolver, 'url_patterns', [])
  File "C:\Users\romanpc\dev\env\env\bookmarks\lib\site-packages\django\utils\functional.py", line 48, in __get__
    res = instance.__dict__[self.name] = self.func(instance)
  File "C:\Users\romanpc\dev\env\env\bookmarks\lib\site-packages\django\urls\resolvers.py", line 589, in url_patterns
    patterns = getattr(self.urlconf_module, "urlpatterns", self.urlconf_module)
  File "C:\Users\romanpc\dev\env\env\bookmarks\lib\site-packages\django\utils\functional.py", line 48, in __get__
    res = instance.__dict__[self.name] = self.func(instance)
  File "C:\Users\romanpc\dev\env\env\bookmarks\lib\site-packages\django\urls\resolvers.py", line 582, in urlconf_module
    return import_module(self.urlconf_name)
  File "C:\Python38\lib\importlib\__init__.py", line 127, in import_module
    return _bootstrap._gcd_import(name[level:], package, level)
  File "<frozen importlib._bootstrap>", line 1014, in _gcd_import
  File "<frozen importlib._bootstrap>", line 991, in _find_and_load
  File "<frozen importlib._bootstrap>", line 975, in _find_and_load_unlocked
  File "<frozen importlib._bootstrap>", line 671, in _load_unlocked
  File "<frozen importlib._bootstrap_external>", line 783, in exec_module
  File "<frozen importlib._bootstrap>", line 219, in _call_with_frames_removed
  File "C:\Users\romanpc\dev\env\env\bookmarks\bookmarks\bookmarks\urls.py", line 24, in <module>
    path('account/', include('account.urls')),
  File "C:\Users\romanpc\dev\env\env\bookmarks\lib\site-packages\django\urls\conf.py", line 34, in include
    urlconf_module = import_module(urlconf_module)
  File "C:\Python38\lib\importlib\__init__.py", line 127, in import_module
    return _bootstrap._gcd_import(name[level:], package, level)
  File "<frozen importlib._bootstrap>", line 1014, in _gcd_import
  File "<frozen importlib._bootstrap>", line 991, in _find_and_load
  File "<frozen importlib._bootstrap>", line 975, in _find_and_load_unlocked
  File "<frozen importlib._bootstrap>", line 671, in _load_unlocked
  File "<frozen importlib._bootstrap_external>", line 783, in exec_module
  File "<frozen importlib._bootstrap>", line 219, in _call_with_frames_removed
  File "C:\Users\romanpc\dev\env\env\bookmarks\bookmarks\account\urls.py", line 16, in <module>
    path('', include('django.contrib.auth.urls')),
NameError: name 'include' is not defined
C:\Users\romanpc\Dev\env\env\bookmarks\bookmarks\account\urls.py changed, reloading.
Watching for file changes with StatReloader
Performing system checks...

System check identified no issues (0 silenced).
October 18, 2020 - 17:07:38
Django version 3.1.2, using settings 'bookmarks.settings'
Starting development server at http://127.0.0.1:8000/
Quit the server with CTRL-BREAK.
Not Found: /
[18/Oct/2020 17:07:45] "GET / HTTP/1.1" 404 2032
Internal Server Error: /account/login/
Traceback (most recent call last):
  File "C:\Users\romanpc\dev\env\env\bookmarks\lib\site-packages\django\urls\base.py", line 72, in reverse
    extra, resolver = resolver.namespace_dict[ns]
KeyError: 'images'

During handling of the above exception, another exception occurred:

Traceback (most recent call last):
  File "C:\Users\romanpc\dev\env\env\bookmarks\lib\site-packages\django\core\handlers\exception.py", line 47, in inner
    response = get_response(request)
  File "C:\Users\romanpc\dev\env\env\bookmarks\lib\site-packages\django\core\handlers\base.py", line 202, in _get_response
    response = response.render()
  File "C:\Users\romanpc\dev\env\env\bookmarks\lib\site-packages\django\template\response.py", line 105, in render
    self.content = self.rendered_content
  File "C:\Users\romanpc\dev\env\env\bookmarks\lib\site-packages\django\template\response.py", line 83, in rendered_content
    return template.render(context, self._request)
  File "C:\Users\romanpc\dev\env\env\bookmarks\lib\site-packages\django\template\backends\django.py", line 61, in render
    return self.template.render(context)
  File "C:\Users\romanpc\dev\env\env\bookmarks\lib\site-packages\django\template\base.py", line 170, in render
    return self._render(context)
  File "C:\Users\romanpc\dev\env\env\bookmarks\lib\site-packages\django\template\base.py", line 162, in _render
    return self.nodelist.render(context)
  File "C:\Users\romanpc\dev\env\env\bookmarks\lib\site-packages\django\template\base.py", line 938, in render
    bit = node.render_annotated(context)
  File "C:\Users\romanpc\dev\env\env\bookmarks\lib\site-packages\django\template\base.py", line 905, in render_annotated
    return self.render(context)
  File "C:\Users\romanpc\dev\env\env\bookmarks\lib\site-packages\django\template\loader_tags.py", line 150, in render
    return compiled_parent._render(context)
  File "C:\Users\romanpc\dev\env\env\bookmarks\lib\site-packages\django\template\base.py", line 162, in _render
    return self.nodelist.render(context)
  File "C:\Users\romanpc\dev\env\env\bookmarks\lib\site-packages\django\template\base.py", line 938, in render
    bit = node.render_annotated(context)
  File "C:\Users\romanpc\dev\env\env\bookmarks\lib\site-packages\django\template\base.py", line 905, in render_annotated
    return self.render(context)
  File "C:\Users\romanpc\dev\env\env\bookmarks\lib\site-packages\django\template\defaulttags.py", line 312, in render
    return nodelist.render(context)
  File "C:\Users\romanpc\dev\env\env\bookmarks\lib\site-packages\django\template\base.py", line 938, in render
    bit = node.render_annotated(context)
  File "C:\Users\romanpc\dev\env\env\bookmarks\lib\site-packages\django\template\base.py", line 905, in render_annotated
    return self.render(context)
  File "C:\Users\romanpc\dev\env\env\bookmarks\lib\site-packages\django\template\defaulttags.py", line 446, in render
    url = reverse(view_name, args=args, kwargs=kwargs, current_app=current_app)
  File "C:\Users\romanpc\dev\env\env\bookmarks\lib\site-packages\django\urls\base.py", line 83, in reverse
    raise NoReverseMatch("%s is not a registered namespace" % key)
django.urls.exceptions.NoReverseMatch: 'images' is not a registered namespace
[18/Oct/2020 17:07:52] "GET /account/login/ HTTP/1.1" 500 146731
Internal Server Error: /account/
Traceback (most recent call last):
  File "C:\Users\romanpc\dev\env\env\bookmarks\lib\site-packages\django\urls\base.py", line 72, in reverse
    extra, resolver = resolver.namespace_dict[ns]
KeyError: 'images'

During handling of the above exception, another exception occurred:

Traceback (most recent call last):
  File "C:\Users\romanpc\dev\env\env\bookmarks\lib\site-packages\django\core\handlers\exception.py", line 47, in inner
    response = get_response(request)
  File "C:\Users\romanpc\dev\env\env\bookmarks\lib\site-packages\django\core\handlers\base.py", line 179, in _get_response
    response = wrapped_callback(request, *callback_args, **callback_kwargs)
  File "C:\Users\romanpc\dev\env\env\bookmarks\lib\site-packages\django\contrib\auth\decorators.py", line 21, in _wrapped_view
    return view_func(request, *args, **kwargs)
  File "C:\Users\romanpc\dev\env\env\bookmarks\bookmarks\account\views.py", line 36, in dashboard
    return render(request,
  File "C:\Users\romanpc\dev\env\env\bookmarks\lib\site-packages\django\shortcuts.py", line 19, in render
    content = loader.render_to_string(template_name, context, request, using=using)
  File "C:\Users\romanpc\dev\env\env\bookmarks\lib\site-packages\django\template\loader.py", line 62, in render_to_string
    return template.render(context, request)
  File "C:\Users\romanpc\dev\env\env\bookmarks\lib\site-packages\django\template\backends\django.py", line 61, in render
    return self.template.render(context)
  File "C:\Users\romanpc\dev\env\env\bookmarks\lib\site-packages\django\template\base.py", line 170, in render
    return self._render(context)
  File "C:\Users\romanpc\dev\env\env\bookmarks\lib\site-packages\django\template\base.py", line 162, in _render
    return self.nodelist.render(context)
  File "C:\Users\romanpc\dev\env\env\bookmarks\lib\site-packages\django\template\base.py", line 938, in render
    bit = node.render_annotated(context)
  File "C:\Users\romanpc\dev\env\env\bookmarks\lib\site-packages\django\template\base.py", line 905, in render_annotated
    return self.render(context)
  File "C:\Users\romanpc\dev\env\env\bookmarks\lib\site-packages\django\template\loader_tags.py", line 150, in render
    return compiled_parent._render(context)
  File "C:\Users\romanpc\dev\env\env\bookmarks\lib\site-packages\django\template\base.py", line 162, in _render
    return self.nodelist.render(context)
  File "C:\Users\romanpc\dev\env\env\bookmarks\lib\site-packages\django\template\base.py", line 938, in render
    bit = node.render_annotated(context)
  File "C:\Users\romanpc\dev\env\env\bookmarks\lib\site-packages\django\template\base.py", line 905, in render_annotated
    return self.render(context)
  File "C:\Users\romanpc\dev\env\env\bookmarks\lib\site-packages\django\template\defaulttags.py", line 312, in render
    return nodelist.render(context)
  File "C:\Users\romanpc\dev\env\env\bookmarks\lib\site-packages\django\template\base.py", line 938, in render
    bit = node.render_annotated(context)
  File "C:\Users\romanpc\dev\env\env\bookmarks\lib\site-packages\django\template\base.py", line 905, in render_annotated
    return self.render(context)
  File "C:\Users\romanpc\dev\env\env\bookmarks\lib\site-packages\django\template\defaulttags.py", line 446, in render
    url = reverse(view_name, args=args, kwargs=kwargs, current_app=current_app)
  File "C:\Users\romanpc\dev\env\env\bookmarks\lib\site-packages\django\urls\base.py", line 83, in reverse
    raise NoReverseMatch("%s is not a registered namespace" % key)
django.urls.exceptions.NoReverseMatch: 'images' is not a registered namespace
[18/Oct/2020 17:07:54] "GET /account/ HTTP/1.1" 500 150943
C:\Users\romanpc\Dev\env\env\bookmarks\bookmarks\account\forms.py changed, reloading.
Watching for file changes with StatReloader
Performing system checks...

System check identified no issues (0 silenced).
October 18, 2020 - 17:08:37
Django version 3.1.2, using settings 'bookmarks.settings'
Starting development server at http://127.0.0.1:8000/
Quit the server with CTRL-BREAK.
C:\Users\romanpc\Dev\env\env\bookmarks\bookmarks\account\forms.py changed, reloading.
Watching for file changes with StatReloader
Performing system checks...

System check identified no issues (0 silenced).
October 18, 2020 - 17:09:41
Django version 3.1.2, using settings 'bookmarks.settings'
Starting development server at http://127.0.0.1:8000/
Quit the server with CTRL-BREAK.
C:\Users\romanpc\Dev\env\env\bookmarks\bookmarks\account\views.py changed, reloading.
Watching for file changes with StatReloader
Performing system checks...

System check identified no issues (0 silenced).
October 18, 2020 - 17:36:10
Django version 3.1.2, using settings 'bookmarks.settings'
Starting development server at http://127.0.0.1:8000/
Quit the server with CTRL-BREAK.
C:\Users\romanpc\Dev\env\env\bookmarks\bookmarks\account\views.py changed, reloading.
Watching for file changes with StatReloader
Performing system checks...

System check identified no issues (0 silenced).
October 18, 2020 - 17:36:47
Django version 3.1.2, using settings 'bookmarks.settings'
Starting development server at http://127.0.0.1:8000/
Quit the server with CTRL-BREAK.
(bookmarks) PS C:\Users\romanpc\dev\env\env\bookmarks\bookmarks> python manage.py runserver
Watching for file changes with StatReloader
Performing system checks...

System check identified no issues (0 silenced).
October 18, 2020 - 17:40:09
Django version 3.1.2, using settings 'bookmarks.settings'
Starting development server at http://127.0.0.1:8000/
Quit the server with CTRL-BREAK.
Internal Server Error: /account/
Traceback (most recent call last):
  File "C:\Users\romanpc\dev\env\env\bookmarks\lib\site-packages\django\urls\base.py", line 72, in reverse
    extra, resolver = resolver.namespace_dict[ns]
KeyError: 'images'

During handling of the above exception, another exception occurred:

Traceback (most recent call last):
  File "C:\Users\romanpc\dev\env\env\bookmarks\lib\site-packages\django\core\handlers\exception.py", line 47, in inner
    response = get_response(request)
  File "C:\Users\romanpc\dev\env\env\bookmarks\lib\site-packages\django\core\handlers\base.py", line 179, in _get_response
    response = wrapped_callback(request, *callback_args, **callback_kwargs)
  File "C:\Users\romanpc\dev\env\env\bookmarks\lib\site-packages\django\contrib\auth\decorators.py", line 21, in _wrapped_view
    return view_func(request, *args, **kwargs)
  File "C:\Users\romanpc\dev\env\env\bookmarks\bookmarks\account\views.py", line 36, in dashboard
    return render(request,
  File "C:\Users\romanpc\dev\env\env\bookmarks\lib\site-packages\django\shortcuts.py", line 19, in render
    content = loader.render_to_string(template_name, context, request, using=using)
  File "C:\Users\romanpc\dev\env\env\bookmarks\lib\site-packages\django\template\loader.py", line 62, in render_to_string
    return template.render(context, request)
  File "C:\Users\romanpc\dev\env\env\bookmarks\lib\site-packages\django\template\backends\django.py", line 61, in render
    return self.template.render(context)
  File "C:\Users\romanpc\dev\env\env\bookmarks\lib\site-packages\django\template\base.py", line 170, in render
    return self._render(context)
  File "C:\Users\romanpc\dev\env\env\bookmarks\lib\site-packages\django\template\base.py", line 162, in _render
    return self.nodelist.render(context)
  File "C:\Users\romanpc\dev\env\env\bookmarks\lib\site-packages\django\template\base.py", line 938, in render
    bit = node.render_annotated(context)
  File "C:\Users\romanpc\dev\env\env\bookmarks\lib\site-packages\django\template\base.py", line 905, in render_annotated
    return self.render(context)
  File "C:\Users\romanpc\dev\env\env\bookmarks\lib\site-packages\django\template\loader_tags.py", line 150, in render
    return compiled_parent._render(context)
  File "C:\Users\romanpc\dev\env\env\bookmarks\lib\site-packages\django\template\base.py", line 162, in _render
    return self.nodelist.render(context)
  File "C:\Users\romanpc\dev\env\env\bookmarks\lib\site-packages\django\template\base.py", line 938, in render
    bit = node.render_annotated(context)
  File "C:\Users\romanpc\dev\env\env\bookmarks\lib\site-packages\django\template\base.py", line 905, in render_annotated
    return self.render(context)
  File "C:\Users\romanpc\dev\env\env\bookmarks\lib\site-packages\django\template\defaulttags.py", line 312, in render
    return nodelist.render(context)
  File "C:\Users\romanpc\dev\env\env\bookmarks\lib\site-packages\django\template\base.py", line 938, in render
    bit = node.render_annotated(context)
  File "C:\Users\romanpc\dev\env\env\bookmarks\lib\site-packages\django\template\base.py", line 905, in render_annotated
    return self.render(context)
  File "C:\Users\romanpc\dev\env\env\bookmarks\lib\site-packages\django\template\defaulttags.py", line 446, in render
    url = reverse(view_name, args=args, kwargs=kwargs, current_app=current_app)
  File "C:\Users\romanpc\dev\env\env\bookmarks\lib\site-packages\django\urls\base.py", line 83, in reverse
    raise NoReverseMatch("%s is not a registered namespace" % key)
django.urls.exceptions.NoReverseMatch: 'images' is not a registered namespace
[18/Oct/2020 17:40:14] "GET /account/ HTTP/1.1" 500 151462
[18/Oct/2020 17:40:17] "GET /account/register HTTP/1.1" 301 0
Internal Server Error: /account/register/
Traceback (most recent call last):
  File "C:\Users\romanpc\dev\env\env\bookmarks\lib\site-packages\django\urls\base.py", line 72, in reverse
    extra, resolver = resolver.namespace_dict[ns]
KeyError: 'images'

During handling of the above exception, another exception occurred:

Traceback (most recent call last):
  File "C:\Users\romanpc\dev\env\env\bookmarks\lib\site-packages\django\core\handlers\exception.py", line 47, in inner
    response = get_response(request)
  File "C:\Users\romanpc\dev\env\env\bookmarks\lib\site-packages\django\core\handlers\base.py", line 179, in _get_response
    response = wrapped_callback(request, *callback_args, **callback_kwargs)
  File "C:\Users\romanpc\dev\env\env\bookmarks\bookmarks\account\views.py", line 60, in register
    return render(request,
  File "C:\Users\romanpc\dev\env\env\bookmarks\lib\site-packages\django\shortcuts.py", line 19, in render
    content = loader.render_to_string(template_name, context, request, using=using)
  File "C:\Users\romanpc\dev\env\env\bookmarks\lib\site-packages\django\template\loader.py", line 62, in render_to_string
    return template.render(context, request)
  File "C:\Users\romanpc\dev\env\env\bookmarks\lib\site-packages\django\template\backends\django.py", line 61, in render
    return self.template.render(context)
  File "C:\Users\romanpc\dev\env\env\bookmarks\lib\site-packages\django\template\base.py", line 170, in render
    return self._render(context)
  File "C:\Users\romanpc\dev\env\env\bookmarks\lib\site-packages\django\template\base.py", line 162, in _render
    return self.nodelist.render(context)
  File "C:\Users\romanpc\dev\env\env\bookmarks\lib\site-packages\django\template\base.py", line 938, in render
    bit = node.render_annotated(context)
  File "C:\Users\romanpc\dev\env\env\bookmarks\lib\site-packages\django\template\base.py", line 905, in render_annotated
    return self.render(context)
  File "C:\Users\romanpc\dev\env\env\bookmarks\lib\site-packages\django\template\loader_tags.py", line 150, in render
    return compiled_parent._render(context)
  File "C:\Users\romanpc\dev\env\env\bookmarks\lib\site-packages\django\template\base.py", line 162, in _render
    return self.nodelist.render(context)
  File "C:\Users\romanpc\dev\env\env\bookmarks\lib\site-packages\django\template\base.py", line 938, in render
    bit = node.render_annotated(context)
  File "C:\Users\romanpc\dev\env\env\bookmarks\lib\site-packages\django\template\base.py", line 905, in render_annotated
    return self.render(context)
  File "C:\Users\romanpc\dev\env\env\bookmarks\lib\site-packages\django\template\defaulttags.py", line 312, in render
    return nodelist.render(context)
  File "C:\Users\romanpc\dev\env\env\bookmarks\lib\site-packages\django\template\base.py", line 938, in render
    bit = node.render_annotated(context)
  File "C:\Users\romanpc\dev\env\env\bookmarks\lib\site-packages\django\template\base.py", line 905, in render_annotated
    return self.render(context)
  File "C:\Users\romanpc\dev\env\env\bookmarks\lib\site-packages\django\template\defaulttags.py", line 446, in render
    url = reverse(view_name, args=args, kwargs=kwargs, current_app=current_app)
  File "C:\Users\romanpc\dev\env\env\bookmarks\lib\site-packages\django\urls\base.py", line 83, in reverse
    raise NoReverseMatch("%s is not a registered namespace" % key)
django.urls.exceptions.NoReverseMatch: 'images' is not a registered namespace
[18/Oct/2020 17:40:17] "GET /account/register/ HTTP/1.1" 500 147700
(bookmarks) PS C:\Users\romanpc\dev\env\env\bookmarks\bookmarks> python manage.py runserver
Watching for file changes with StatReloader
Performing system checks...

System check identified no issues (0 silenced).
October 18, 2020 - 17:40:49
Django version 3.1.2, using settings 'bookmarks.settings'
Starting development server at http://127.0.0.1:8000/
Quit the server with CTRL-BREAK.
C:\Users\romanpc\Dev\env\env\bookmarks\bookmarks\account\models.py changed, reloading.
Watching for file changes with StatReloader
Performing system checks...

System check identified no issues (0 silenced).
October 18, 2020 - 17:42:57
Django version 3.1.2, using settings 'bookmarks.settings'
Starting development server at http://127.0.0.1:8000/
Quit the server with CTRL-BREAK.
C:\Users\romanpc\Dev\env\env\bookmarks\bookmarks\account\models.py changed, reloading.
Watching for file changes with StatReloader
Performing system checks...

Exception in thread django-main-thread:
Traceback (most recent call last):
  File "C:\Python38\lib\threading.py", line 932, in _bootstrap_inner
    self.run()
  File "C:\Python38\lib\threading.py", line 870, in run
    self._target(*self._args, **self._kwargs)
  File "C:\Users\romanpc\dev\env\env\bookmarks\lib\site-packages\django\utils\autoreload.py", line 53, in wrapper
    fn(*args, **kwargs)
  File "C:\Users\romanpc\dev\env\env\bookmarks\lib\site-packages\django\core\management\commands\runserver.py", line 118, in inner_run
    self.check(display_num_errors=True)
  File "C:\Users\romanpc\dev\env\env\bookmarks\lib\site-packages\django\core\management\base.py", line 442, in check
    raise SystemCheckError(msg)
django.core.management.base.SystemCheckError: SystemCheckError: System check identified some issues:

ERRORS:
account.Profile.photo: (fields.E210) Cannot use ImageField because Pillow is not installed.
        HINT: Get Pillow at https://pypi.org/project/Pillow/ or run command "python -m pip install Pillow".

System check identified 1 issue (0 silenced).
(bookmarks) PS C:\Users\romanpc\dev\env\env\bookmarks\bookmarks> pip install Pillow==7.0.0
Collecting Pillow==7.0.0
  Downloading Pillow-7.0.0-cp38-cp38-win_amd64.whl (2.0 MB)
     |████████████████████████████████| 2.0 MB 2.2 MB/s
Installing collected packages: Pillow
Successfully installed Pillow-7.0.0
WARNING: You are using pip version 20.1.1; however, version 20.2.4 is available.
You should consider upgrading via the 'c:\users\romanpc\dev\env\env\bookmarks\scripts\python.exe -m pip install --upgrade pip' command.
(bookmarks) PS C:\Users\romanpc\dev\env\env\bookmarks\bookmarks> python manage.py makemigrations
Traceback (most recent call last):
  File "manage.py", line 22, in <module>
    main()
  File "manage.py", line 18, in main
    execute_from_command_line(sys.argv)
  File "C:\Users\romanpc\dev\env\env\bookmarks\lib\site-packages\django\core\management\__init__.py", line 401, in execute_from_command_line
    utility.execute()
  File "C:\Users\romanpc\dev\env\env\bookmarks\lib\site-packages\django\core\management\__init__.py", line 345, in execute
    settings.INSTALLED_APPS
  File "C:\Users\romanpc\dev\env\env\bookmarks\lib\site-packages\django\conf\__init__.py", line 83, in __getattr__
    self._setup(name)
  File "C:\Users\romanpc\dev\env\env\bookmarks\lib\site-packages\django\conf\__init__.py", line 70, in _setup
    self._wrapped = Settings(settings_module)
  File "C:\Users\romanpc\dev\env\env\bookmarks\lib\site-packages\django\conf\__init__.py", line 177, in __init__
    mod = importlib.import_module(self.SETTINGS_MODULE)
  File "C:\Python38\lib\importlib\__init__.py", line 127, in import_module
    return _bootstrap._gcd_import(name[level:], package, level)
  File "<frozen importlib._bootstrap>", line 1014, in _gcd_import
  File "<frozen importlib._bootstrap>", line 991, in _find_and_load
  File "<frozen importlib._bootstrap>", line 975, in _find_and_load_unlocked
  File "<frozen importlib._bootstrap>", line 671, in _load_unlocked
  File "<frozen importlib._bootstrap_external>", line 783, in exec_module
  File "<frozen importlib._bootstrap>", line 219, in _call_with_frames_removed
  File "C:\Users\romanpc\dev\env\env\bookmarks\bookmarks\bookmarks\settings.py", line 136, in <module>
    MEDIA_ROOT = os.path.join(BASE_DIR, 'media/')
NameError: name 'os' is not defined
(bookmarks) PS C:\Users\romanpc\dev\env\env\bookmarks\bookmarks> python manage.py migrate
Traceback (most recent call last):
  File "manage.py", line 22, in <module>
    main()
  File "manage.py", line 18, in main
    execute_from_command_line(sys.argv)
  File "C:\Users\romanpc\dev\env\env\bookmarks\lib\site-packages\django\core\management\__init__.py", line 401, in execute_from_command_line
    utility.execute()
  File "C:\Users\romanpc\dev\env\env\bookmarks\lib\site-packages\django\core\management\__init__.py", line 345, in execute
    settings.INSTALLED_APPS
  File "C:\Users\romanpc\dev\env\env\bookmarks\lib\site-packages\django\conf\__init__.py", line 83, in __getattr__
    self._setup(name)
  File "C:\Users\romanpc\dev\env\env\bookmarks\lib\site-packages\django\conf\__init__.py", line 70, in _setup
    self._wrapped = Settings(settings_module)
  File "C:\Users\romanpc\dev\env\env\bookmarks\lib\site-packages\django\conf\__init__.py", line 177, in __init__
    mod = importlib.import_module(self.SETTINGS_MODULE)
  File "C:\Python38\lib\importlib\__init__.py", line 127, in import_module
    return _bootstrap._gcd_import(name[level:], package, level)
  File "<frozen importlib._bootstrap>", line 1014, in _gcd_import
  File "<frozen importlib._bootstrap>", line 991, in _find_and_load
  File "<frozen importlib._bootstrap>", line 975, in _find_and_load_unlocked
  File "<frozen importlib._bootstrap>", line 671, in _load_unlocked
  File "<frozen importlib._bootstrap_external>", line 783, in exec_module
  File "<frozen importlib._bootstrap>", line 219, in _call_with_frames_removed
  File "C:\Users\romanpc\dev\env\env\bookmarks\bookmarks\bookmarks\settings.py", line 136, in <module>
    MEDIA_ROOT = os.path.join(BASE_DIR, 'media/')
NameError: name 'os' is not defined
(bookmarks) PS C:\Users\romanpc\dev\env\env\bookmarks\bookmarks> python manage.py runserver
Traceback (most recent call last):
  File "manage.py", line 22, in <module>
    main()
  File "manage.py", line 18, in main
    execute_from_command_line(sys.argv)
  File "C:\Users\romanpc\dev\env\env\bookmarks\lib\site-packages\django\core\management\__init__.py", line 401, in execute_from_command_line
    utility.execute()
  File "C:\Users\romanpc\dev\env\env\bookmarks\lib\site-packages\django\core\management\__init__.py", line 345, in execute
    settings.INSTALLED_APPS
  File "C:\Users\romanpc\dev\env\env\bookmarks\lib\site-packages\django\conf\__init__.py", line 83, in __getattr__
    self._setup(name)
  File "C:\Users\romanpc\dev\env\env\bookmarks\lib\site-packages\django\conf\__init__.py", line 70, in _setup
    self._wrapped = Settings(settings_module)
  File "C:\Users\romanpc\dev\env\env\bookmarks\lib\site-packages\django\conf\__init__.py", line 177, in __init__
    mod = importlib.import_module(self.SETTINGS_MODULE)
  File "C:\Python38\lib\importlib\__init__.py", line 127, in import_module
    return _bootstrap._gcd_import(name[level:], package, level)
  File "<frozen importlib._bootstrap>", line 1014, in _gcd_import
  File "<frozen importlib._bootstrap>", line 991, in _find_and_load
  File "<frozen importlib._bootstrap>", line 975, in _find_and_load_unlocked
  File "<frozen importlib._bootstrap>", line 671, in _load_unlocked
  File "<frozen importlib._bootstrap_external>", line 783, in exec_module
  File "<frozen importlib._bootstrap>", line 219, in _call_with_frames_removed
  File "C:\Users\romanpc\dev\env\env\bookmarks\bookmarks\bookmarks\settings.py", line 136, in <module>
    MEDIA_ROOT = os.path.join(BASE_DIR, 'media/')
NameError: name 'os' is not defined
(bookmarks) PS C:\Users\romanpc\dev\env\env\bookmarks\bookmarks> python manage.py runserver
Traceback (most recent call last):
  File "manage.py", line 22, in <module>
    main()
  File "manage.py", line 18, in main
    execute_from_command_line(sys.argv)
  File "C:\Users\romanpc\dev\env\env\bookmarks\lib\site-packages\django\core\management\__init__.py", line 401, in execute_from_command_line
    utility.execute()
  File "C:\Users\romanpc\dev\env\env\bookmarks\lib\site-packages\django\core\management\__init__.py", line 345, in execute
    settings.INSTALLED_APPS
  File "C:\Users\romanpc\dev\env\env\bookmarks\lib\site-packages\django\conf\__init__.py", line 83, in __getattr__
    self._setup(name)
  File "C:\Users\romanpc\dev\env\env\bookmarks\lib\site-packages\django\conf\__init__.py", line 70, in _setup
    self._wrapped = Settings(settings_module)
  File "C:\Users\romanpc\dev\env\env\bookmarks\lib\site-packages\django\conf\__init__.py", line 177, in __init__
    mod = importlib.import_module(self.SETTINGS_MODULE)
  File "C:\Python38\lib\importlib\__init__.py", line 127, in import_module
    return _bootstrap._gcd_import(name[level:], package, level)
  File "<frozen importlib._bootstrap>", line 1014, in _gcd_import
  File "<frozen importlib._bootstrap>", line 991, in _find_and_load
  File "<frozen importlib._bootstrap>", line 975, in _find_and_load_unlocked
  File "<frozen importlib._bootstrap>", line 671, in _load_unlocked
  File "<frozen importlib._bootstrap_external>", line 783, in exec_module
  File "<frozen importlib._bootstrap>", line 219, in _call_with_frames_removed
  File "C:\Users\romanpc\dev\env\env\bookmarks\bookmarks\bookmarks\settings.py", line 136, in <module>
    MEDIA_ROOT = os.path.join(BASE_DIR, 'media/')
NameError: name 'os' is not defined
(bookmarks) PS C:\Users\romanpc\dev\env\env\bookmarks\bookmarks> python manage.py runserver
Watching for file changes with StatReloader
Performing system checks...

System check identified no issues (0 silenced).
October 18, 2020 - 17:52:48
Django version 3.1.2, using settings 'bookmarks.settings'
Starting development server at http://127.0.0.1:8000/
Quit the server with CTRL-BREAK.
(bookmarks) PS C:\Users\romanpc\dev\env\env\bookmarks\bookmarks> python manage.py makemigrations
Migrations for 'account':
  account\migrations\0001_initial.py
    - Create model Profile
(bookmarks) PS C:\Users\romanpc\dev\env\env\bookmarks\bookmarks> python manage.py migrate
Operations to perform:
  Apply all migrations: account, admin, auth, contenttypes, sessions
Running migrations:
  Applying account.0001_initial... OK
(bookmarks) PS C:\Users\romanpc\dev\env\env\bookmarks\bookmarks> python manage.py runserver
Watching for file changes with StatReloader
Performing system checks...

System check identified no issues (0 silenced).
October 18, 2020 - 17:53:09
Django version 3.1.2, using settings 'bookmarks.settings'
Starting development server at http://127.0.0.1:8000/
Quit the server with CTRL-BREAK.
Internal Server Error: /account/register/
Traceback (most recent call last):
  File "C:\Users\romanpc\dev\env\env\bookmarks\lib\site-packages\django\urls\base.py", line 72, in reverse
    extra, resolver = resolver.namespace_dict[ns]
KeyError: 'images'

During handling of the above exception, another exception occurred:

Traceback (most recent call last):
  File "C:\Users\romanpc\dev\env\env\bookmarks\lib\site-packages\django\core\handlers\exception.py", line 47, in inner
    response = get_response(request)
  File "C:\Users\romanpc\dev\env\env\bookmarks\lib\site-packages\django\core\handlers\base.py", line 179, in _get_response
    response = wrapped_callback(request, *callback_args, **callback_kwargs)
  File "C:\Users\romanpc\dev\env\env\bookmarks\bookmarks\account\views.py", line 60, in register
    return render(request,
  File "C:\Users\romanpc\dev\env\env\bookmarks\lib\site-packages\django\shortcuts.py", line 19, in render
    content = loader.render_to_string(template_name, context, request, using=using)
  File "C:\Users\romanpc\dev\env\env\bookmarks\lib\site-packages\django\template\loader.py", line 62, in render_to_string
    return template.render(context, request)
  File "C:\Users\romanpc\dev\env\env\bookmarks\lib\site-packages\django\template\backends\django.py", line 61, in render
    return self.template.render(context)
  File "C:\Users\romanpc\dev\env\env\bookmarks\lib\site-packages\django\template\base.py", line 170, in render
    return self._render(context)
  File "C:\Users\romanpc\dev\env\env\bookmarks\lib\site-packages\django\template\base.py", line 162, in _render
    return self.nodelist.render(context)
  File "C:\Users\romanpc\dev\env\env\bookmarks\lib\site-packages\django\template\base.py", line 938, in render
    bit = node.render_annotated(context)
  File "C:\Users\romanpc\dev\env\env\bookmarks\lib\site-packages\django\template\base.py", line 905, in render_annotated
    return self.render(context)
  File "C:\Users\romanpc\dev\env\env\bookmarks\lib\site-packages\django\template\loader_tags.py", line 150, in render
    return compiled_parent._render(context)
  File "C:\Users\romanpc\dev\env\env\bookmarks\lib\site-packages\django\template\base.py", line 162, in _render
    return self.nodelist.render(context)
  File "C:\Users\romanpc\dev\env\env\bookmarks\lib\site-packages\django\template\base.py", line 938, in render
    bit = node.render_annotated(context)
  File "C:\Users\romanpc\dev\env\env\bookmarks\lib\site-packages\django\template\base.py", line 905, in render_annotated
    return self.render(context)
  File "C:\Users\romanpc\dev\env\env\bookmarks\lib\site-packages\django\template\defaulttags.py", line 312, in render
    return nodelist.render(context)
  File "C:\Users\romanpc\dev\env\env\bookmarks\lib\site-packages\django\template\base.py", line 938, in render
    bit = node.render_annotated(context)
  File "C:\Users\romanpc\dev\env\env\bookmarks\lib\site-packages\django\template\base.py", line 905, in render_annotated
    return self.render(context)
  File "C:\Users\romanpc\dev\env\env\bookmarks\lib\site-packages\django\template\defaulttags.py", line 446, in render
    url = reverse(view_name, args=args, kwargs=kwargs, current_app=current_app)
  File "C:\Users\romanpc\dev\env\env\bookmarks\lib\site-packages\django\urls\base.py", line 83, in reverse
    raise NoReverseMatch("%s is not a registered namespace" % key)
django.urls.exceptions.NoReverseMatch: 'images' is not a registered namespace
[18/Oct/2020 17:53:11] "GET /account/register/ HTTP/1.1" 500 147906
Not Found: /
[18/Oct/2020 17:53:13] "GET / HTTP/1.1" 404 2158
[18/Oct/2020 17:53:18] "GET /account HTTP/1.1" 301 0
Internal Server Error: /account/
Traceback (most recent call last):
  File "C:\Users\romanpc\dev\env\env\bookmarks\lib\site-packages\django\urls\base.py", line 72, in reverse
    extra, resolver = resolver.namespace_dict[ns]
KeyError: 'images'

During handling of the above exception, another exception occurred:

Traceback (most recent call last):
  File "C:\Users\romanpc\dev\env\env\bookmarks\lib\site-packages\django\core\handlers\exception.py", line 47, in inner
    response = get_response(request)
  File "C:\Users\romanpc\dev\env\env\bookmarks\lib\site-packages\django\core\handlers\base.py", line 179, in _get_response
    response = wrapped_callback(request, *callback_args, **callback_kwargs)
  File "C:\Users\romanpc\dev\env\env\bookmarks\lib\site-packages\django\contrib\auth\decorators.py", line 21, in _wrapped_view
    return view_func(request, *args, **kwargs)
  File "C:\Users\romanpc\dev\env\env\bookmarks\bookmarks\account\views.py", line 36, in dashboard
    return render(request,
  File "C:\Users\romanpc\dev\env\env\bookmarks\lib\site-packages\django\shortcuts.py", line 19, in render
    content = loader.render_to_string(template_name, context, request, using=using)
  File "C:\Users\romanpc\dev\env\env\bookmarks\lib\site-packages\django\template\loader.py", line 62, in render_to_string
    return template.render(context, request)
  File "C:\Users\romanpc\dev\env\env\bookmarks\lib\site-packages\django\template\backends\django.py", line 61, in render
    return self.template.render(context)
  File "C:\Users\romanpc\dev\env\env\bookmarks\lib\site-packages\django\template\base.py", line 170, in render
    return self._render(context)
  File "C:\Users\romanpc\dev\env\env\bookmarks\lib\site-packages\django\template\base.py", line 162, in _render
    return self.nodelist.render(context)
  File "C:\Users\romanpc\dev\env\env\bookmarks\lib\site-packages\django\template\base.py", line 938, in render
    bit = node.render_annotated(context)
  File "C:\Users\romanpc\dev\env\env\bookmarks\lib\site-packages\django\template\base.py", line 905, in render_annotated
    return self.render(context)
  File "C:\Users\romanpc\dev\env\env\bookmarks\lib\site-packages\django\template\loader_tags.py", line 150, in render
    return compiled_parent._render(context)
  File "C:\Users\romanpc\dev\env\env\bookmarks\lib\site-packages\django\template\base.py", line 162, in _render
    return self.nodelist.render(context)
  File "C:\Users\romanpc\dev\env\env\bookmarks\lib\site-packages\django\template\base.py", line 938, in render
    bit = node.render_annotated(context)
  File "C:\Users\romanpc\dev\env\env\bookmarks\lib\site-packages\django\template\base.py", line 905, in render_annotated
    return self.render(context)
  File "C:\Users\romanpc\dev\env\env\bookmarks\lib\site-packages\django\template\defaulttags.py", line 312, in render
    return nodelist.render(context)
  File "C:\Users\romanpc\dev\env\env\bookmarks\lib\site-packages\django\template\base.py", line 938, in render
    bit = node.render_annotated(context)
  File "C:\Users\romanpc\dev\env\env\bookmarks\lib\site-packages\django\template\base.py", line 905, in render_annotated
    return self.render(context)
  File "C:\Users\romanpc\dev\env\env\bookmarks\lib\site-packages\django\template\defaulttags.py", line 446, in render
    url = reverse(view_name, args=args, kwargs=kwargs, current_app=current_app)
  File "C:\Users\romanpc\dev\env\env\bookmarks\lib\site-packages\django\urls\base.py", line 83, in reverse
    raise NoReverseMatch("%s is not a registered namespace" % key)
django.urls.exceptions.NoReverseMatch: 'images' is not a registered namespace
[18/Oct/2020 17:53:18] "GET /account/ HTTP/1.1" 500 151394
[18/Oct/2020 17:53:33] "GET /admin HTTP/1.1" 301 0
[18/Oct/2020 17:53:33] "GET /admin/ HTTP/1.1" 200 3975
[18/Oct/2020 17:53:33] "GET /static/admin/css/nav_sidebar.css HTTP/1.1" 200 2138
[18/Oct/2020 17:53:33] "GET /static/admin/css/dashboard.css HTTP/1.1" 200 380
[18/Oct/2020 17:53:33] "GET /static/admin/css/base.css HTTP/1.1" 200 16307
[18/Oct/2020 17:53:33] "GET /static/admin/css/responsive.css HTTP/1.1" 200 18294
[18/Oct/2020 17:53:33] "GET /static/admin/js/nav_sidebar.js HTTP/1.1" 200 1360
[18/Oct/2020 17:53:33] "GET /static/admin/css/fonts.css HTTP/1.1" 200 423
[18/Oct/2020 17:53:33] "GET /static/admin/img/icon-changelink.svg HTTP/1.1" 200 380
[18/Oct/2020 17:53:33] "GET /static/admin/img/icon-addlink.svg HTTP/1.1" 200 331
[18/Oct/2020 17:53:33] "GET /static/admin/fonts/Roboto-Light-webfont.woff HTTP/1.1" 200 85692
[18/Oct/2020 17:53:33] "GET /static/admin/fonts/Roboto-Bold-webfont.woff HTTP/1.1" 200 86184
[18/Oct/2020 17:53:33] "GET /static/admin/fonts/Roboto-Regular-webfont.woff HTTP/1.1" 200 85876
(bookmarks) PS C:\Users\romanpc\dev\env\env\bookmarks\bookmarks> python manage.py runserver
Watching for file changes with StatReloader
Performing system checks...

Exception in thread django-main-thread:
Traceback (most recent call last):
  File "C:\Python38\lib\threading.py", line 932, in _bootstrap_inner
    self.run()
  File "C:\Python38\lib\threading.py", line 870, in run
    self._target(*self._args, **self._kwargs)
  File "C:\Users\romanpc\dev\env\env\bookmarks\lib\site-packages\django\utils\autoreload.py", line 53, in wrapper
    fn(*args, **kwargs)
  File "C:\Users\romanpc\dev\env\env\bookmarks\lib\site-packages\django\core\management\commands\runserver.py", line 118, in inner_run
    self.check(display_num_errors=True)
  File "C:\Users\romanpc\dev\env\env\bookmarks\lib\site-packages\django\core\management\base.py", line 392, in check
    all_issues = checks.run_checks(
  File "C:\Users\romanpc\dev\env\env\bookmarks\lib\site-packages\django\core\checks\registry.py", line 70, in run_checks
    new_errors = check(app_configs=app_configs, databases=databases)
  File "C:\Users\romanpc\dev\env\env\bookmarks\lib\site-packages\django\core\checks\urls.py", line 40, in check_url_namespaces_unique
    all_namespaces = _load_all_namespaces(resolver)
  File "C:\Users\romanpc\dev\env\env\bookmarks\lib\site-packages\django\core\checks\urls.py", line 57, in _load_all_namespaces
    url_patterns = getattr(resolver, 'url_patterns', [])
  File "C:\Users\romanpc\dev\env\env\bookmarks\lib\site-packages\django\utils\functional.py", line 48, in __get__
    res = instance.__dict__[self.name] = self.func(instance)
  File "C:\Users\romanpc\dev\env\env\bookmarks\lib\site-packages\django\urls\resolvers.py", line 589, in url_patterns
    patterns = getattr(self.urlconf_module, "urlpatterns", self.urlconf_module)
  File "C:\Users\romanpc\dev\env\env\bookmarks\lib\site-packages\django\utils\functional.py", line 48, in __get__
    res = instance.__dict__[self.name] = self.func(instance)
  File "C:\Users\romanpc\dev\env\env\bookmarks\lib\site-packages\django\urls\resolvers.py", line 582, in urlconf_module
    return import_module(self.urlconf_name)
  File "C:\Python38\lib\importlib\__init__.py", line 127, in import_module
    return _bootstrap._gcd_import(name[level:], package, level)
  File "<frozen importlib._bootstrap>", line 1014, in _gcd_import
  File "<frozen importlib._bootstrap>", line 991, in _find_and_load
  File "<frozen importlib._bootstrap>", line 975, in _find_and_load_unlocked
  File "<frozen importlib._bootstrap>", line 671, in _load_unlocked
  File "<frozen importlib._bootstrap_external>", line 783, in exec_module
  File "<frozen importlib._bootstrap>", line 219, in _call_with_frames_removed
  File "C:\Users\romanpc\dev\env\env\bookmarks\bookmarks\bookmarks\urls.py", line 26, in <module>
    path('account/', include('account.urls')),
  File "C:\Users\romanpc\dev\env\env\bookmarks\lib\site-packages\django\urls\conf.py", line 34, in include
    urlconf_module = import_module(urlconf_module)
  File "C:\Python38\lib\importlib\__init__.py", line 127, in import_module
    return _bootstrap._gcd_import(name[level:], package, level)
  File "<frozen importlib._bootstrap>", line 1014, in _gcd_import
  File "<frozen importlib._bootstrap>", line 991, in _find_and_load
  File "<frozen importlib._bootstrap>", line 975, in _find_and_load_unlocked
  File "<frozen importlib._bootstrap>", line 671, in _load_unlocked
  File "<frozen importlib._bootstrap_external>", line 783, in exec_module
  File "<frozen importlib._bootstrap>", line 219, in _call_with_frames_removed
  File "C:\Users\romanpc\dev\env\env\bookmarks\bookmarks\account\urls.py", line 3, in <module>
    from . import views
  File "C:\Users\romanpc\dev\env\env\bookmarks\bookmarks\account\views.py", line 6
    from .forms import LoginForm, UserRegistrationForm, \UserEditForm, ProfileEditForm
                                                                                     ^
SyntaxError: unexpected character after line continuation character
(bookmarks) PS C:\Users\romanpc\dev\env\env\bookmarks\bookmarks> python manage.py runserver
Watching for file changes with StatReloader
Performing system checks...

Exception in thread django-main-thread:
Traceback (most recent call last):
  File "C:\Python38\lib\threading.py", line 932, in _bootstrap_inner
    self.run()
  File "C:\Python38\lib\threading.py", line 870, in run
    self._target(*self._args, **self._kwargs)
  File "C:\Users\romanpc\dev\env\env\bookmarks\lib\site-packages\django\utils\autoreload.py", line 53, in wrapper
    fn(*args, **kwargs)
  File "C:\Users\romanpc\dev\env\env\bookmarks\lib\site-packages\django\core\management\commands\runserver.py", line 118, in inner_run
    self.check(display_num_errors=True)
  File "C:\Users\romanpc\dev\env\env\bookmarks\lib\site-packages\django\core\management\base.py", line 392, in check
    all_issues = checks.run_checks(
  File "C:\Users\romanpc\dev\env\env\bookmarks\lib\site-packages\django\core\checks\registry.py", line 70, in run_checks
    new_errors = check(app_configs=app_configs, databases=databases)
  File "C:\Users\romanpc\dev\env\env\bookmarks\lib\site-packages\django\core\checks\urls.py", line 40, in check_url_namespaces_unique
    all_namespaces = _load_all_namespaces(resolver)
  File "C:\Users\romanpc\dev\env\env\bookmarks\lib\site-packages\django\core\checks\urls.py", line 57, in _load_all_namespaces
    url_patterns = getattr(resolver, 'url_patterns', [])
  File "C:\Users\romanpc\dev\env\env\bookmarks\lib\site-packages\django\utils\functional.py", line 48, in __get__
    res = instance.__dict__[self.name] = self.func(instance)
  File "C:\Users\romanpc\dev\env\env\bookmarks\lib\site-packages\django\urls\resolvers.py", line 589, in url_patterns
    patterns = getattr(self.urlconf_module, "urlpatterns", self.urlconf_module)
  File "C:\Users\romanpc\dev\env\env\bookmarks\lib\site-packages\django\utils\functional.py", line 48, in __get__
    res = instance.__dict__[self.name] = self.func(instance)
  File "C:\Users\romanpc\dev\env\env\bookmarks\lib\site-packages\django\urls\resolvers.py", line 582, in urlconf_module
    return import_module(self.urlconf_name)
  File "C:\Python38\lib\importlib\__init__.py", line 127, in import_module
    return _bootstrap._gcd_import(name[level:], package, level)
  File "<frozen importlib._bootstrap>", line 1014, in _gcd_import
  File "<frozen importlib._bootstrap>", line 991, in _find_and_load
  File "<frozen importlib._bootstrap>", line 975, in _find_and_load_unlocked
  File "<frozen importlib._bootstrap>", line 671, in _load_unlocked
  File "<frozen importlib._bootstrap_external>", line 783, in exec_module
  File "<frozen importlib._bootstrap>", line 219, in _call_with_frames_removed
  File "C:\Users\romanpc\dev\env\env\bookmarks\bookmarks\bookmarks\urls.py", line 26, in <module>
    path('account/', include('account.urls')),
  File "C:\Users\romanpc\dev\env\env\bookmarks\lib\site-packages\django\urls\conf.py", line 34, in include
    urlconf_module = import_module(urlconf_module)
  File "C:\Python38\lib\importlib\__init__.py", line 127, in import_module
    return _bootstrap._gcd_import(name[level:], package, level)
  File "<frozen importlib._bootstrap>", line 1014, in _gcd_import
  File "<frozen importlib._bootstrap>", line 991, in _find_and_load
  File "<frozen importlib._bootstrap>", line 975, in _find_and_load_unlocked
  File "<frozen importlib._bootstrap>", line 671, in _load_unlocked
  File "<frozen importlib._bootstrap_external>", line 783, in exec_module
  File "<frozen importlib._bootstrap>", line 219, in _call_with_frames_removed
  File "C:\Users\romanpc\dev\env\env\bookmarks\bookmarks\account\urls.py", line 3, in <module>
    from . import views
  File "C:\Users\romanpc\dev\env\env\bookmarks\bookmarks\account\views.py", line 6
    from .forms import LoginForm, UserRegistrationForm, \UserEditForm, ProfileEditForm
                                                                                     ^
SyntaxError: unexpected character after line continuation character
C:\Users\romanpc\Dev\env\env\bookmarks\bookmarks\account\views.py changed, reloading.
Watching for file changes with StatReloader
Performing system checks...

System check identified no issues (0 silenced).
October 18, 2020 - 18:12:29
Django version 3.1.2, using settings 'bookmarks.settings'
Starting development server at http://127.0.0.1:8000/
Quit the server with CTRL-BREAK.
Internal Server Error: /account/
Traceback (most recent call last):
  File "C:\Users\romanpc\dev\env\env\bookmarks\lib\site-packages\django\urls\base.py", line 72, in reverse
    extra, resolver = resolver.namespace_dict[ns]
KeyError: 'images'

During handling of the above exception, another exception occurred:

Traceback (most recent call last):
  File "C:\Users\romanpc\dev\env\env\bookmarks\lib\site-packages\django\core\handlers\exception.py", line 47, in inner
    response = get_response(request)
  File "C:\Users\romanpc\dev\env\env\bookmarks\lib\site-packages\django\core\handlers\base.py", line 179, in _get_response
    response = wrapped_callback(request, *callback_args, **callback_kwargs)
  File "C:\Users\romanpc\dev\env\env\bookmarks\lib\site-packages\django\contrib\auth\decorators.py", line 21, in _wrapped_view
    return view_func(request, *args, **kwargs)
  File "C:\Users\romanpc\dev\env\env\bookmarks\bookmarks\account\views.py", line 37, in dashboard
    return render(request,
  File "C:\Users\romanpc\dev\env\env\bookmarks\lib\site-packages\django\shortcuts.py", line 19, in render
    content = loader.render_to_string(template_name, context, request, using=using)
  File "C:\Users\romanpc\dev\env\env\bookmarks\lib\site-packages\django\template\loader.py", line 62, in render_to_string
    return template.render(context, request)
  File "C:\Users\romanpc\dev\env\env\bookmarks\lib\site-packages\django\template\backends\django.py", line 61, in render
    return self.template.render(context)
  File "C:\Users\romanpc\dev\env\env\bookmarks\lib\site-packages\django\template\base.py", line 170, in render
    return self._render(context)
  File "C:\Users\romanpc\dev\env\env\bookmarks\lib\site-packages\django\template\base.py", line 162, in _render
    return self.nodelist.render(context)
  File "C:\Users\romanpc\dev\env\env\bookmarks\lib\site-packages\django\template\base.py", line 938, in render
    bit = node.render_annotated(context)
  File "C:\Users\romanpc\dev\env\env\bookmarks\lib\site-packages\django\template\base.py", line 905, in render_annotated
    return self.render(context)
  File "C:\Users\romanpc\dev\env\env\bookmarks\lib\site-packages\django\template\loader_tags.py", line 150, in render
    return compiled_parent._render(context)
  File "C:\Users\romanpc\dev\env\env\bookmarks\lib\site-packages\django\template\base.py", line 162, in _render
    return self.nodelist.render(context)
  File "C:\Users\romanpc\dev\env\env\bookmarks\lib\site-packages\django\template\base.py", line 938, in render
    bit = node.render_annotated(context)
  File "C:\Users\romanpc\dev\env\env\bookmarks\lib\site-packages\django\template\base.py", line 905, in render_annotated
    return self.render(context)
  File "C:\Users\romanpc\dev\env\env\bookmarks\lib\site-packages\django\template\defaulttags.py", line 312, in render
    return nodelist.render(context)
  File "C:\Users\romanpc\dev\env\env\bookmarks\lib\site-packages\django\template\base.py", line 938, in render
    bit = node.render_annotated(context)
  File "C:\Users\romanpc\dev\env\env\bookmarks\lib\site-packages\django\template\base.py", line 905, in render_annotated
    return self.render(context)
  File "C:\Users\romanpc\dev\env\env\bookmarks\lib\site-packages\django\template\defaulttags.py", line 446, in render
    url = reverse(view_name, args=args, kwargs=kwargs, current_app=current_app)
  File "C:\Users\romanpc\dev\env\env\bookmarks\lib\site-packages\django\urls\base.py", line 83, in reverse
    raise NoReverseMatch("%s is not a registered namespace" % key)
django.urls.exceptions.NoReverseMatch: 'images' is not a registered namespace
[18/Oct/2020 18:12:40] "GET /account/ HTTP/1.1" 500 151394
Internal Server Error: /account/register/
Traceback (most recent call last):
  File "C:\Users\romanpc\dev\env\env\bookmarks\lib\site-packages\django\urls\base.py", line 72, in reverse
    extra, resolver = resolver.namespace_dict[ns]
KeyError: 'images'

During handling of the above exception, another exception occurred:

Traceback (most recent call last):
  File "C:\Users\romanpc\dev\env\env\bookmarks\lib\site-packages\django\core\handlers\exception.py", line 47, in inner
    response = get_response(request)
  File "C:\Users\romanpc\dev\env\env\bookmarks\lib\site-packages\django\core\handlers\base.py", line 179, in _get_response
    response = wrapped_callback(request, *callback_args, **callback_kwargs)
  File "C:\Users\romanpc\dev\env\env\bookmarks\bookmarks\account\views.py", line 61, in register
    return render(request,
  File "C:\Users\romanpc\dev\env\env\bookmarks\lib\site-packages\django\shortcuts.py", line 19, in render
    content = loader.render_to_string(template_name, context, request, using=using)
  File "C:\Users\romanpc\dev\env\env\bookmarks\lib\site-packages\django\template\loader.py", line 62, in render_to_string
    return template.render(context, request)
  File "C:\Users\romanpc\dev\env\env\bookmarks\lib\site-packages\django\template\backends\django.py", line 61, in render
    return self.template.render(context)
  File "C:\Users\romanpc\dev\env\env\bookmarks\lib\site-packages\django\template\base.py", line 170, in render
    return self._render(context)
  File "C:\Users\romanpc\dev\env\env\bookmarks\lib\site-packages\django\template\base.py", line 162, in _render
    return self.nodelist.render(context)
  File "C:\Users\romanpc\dev\env\env\bookmarks\lib\site-packages\django\template\base.py", line 938, in render
    bit = node.render_annotated(context)
  File "C:\Users\romanpc\dev\env\env\bookmarks\lib\site-packages\django\template\base.py", line 905, in render_annotated
    return self.render(context)
  File "C:\Users\romanpc\dev\env\env\bookmarks\lib\site-packages\django\template\loader_tags.py", line 150, in render
    return compiled_parent._render(context)
  File "C:\Users\romanpc\dev\env\env\bookmarks\lib\site-packages\django\template\base.py", line 162, in _render
    return self.nodelist.render(context)
  File "C:\Users\romanpc\dev\env\env\bookmarks\lib\site-packages\django\template\base.py", line 938, in render
    bit = node.render_annotated(context)
  File "C:\Users\romanpc\dev\env\env\bookmarks\lib\site-packages\django\template\base.py", line 905, in render_annotated
    return self.render(context)
  File "C:\Users\romanpc\dev\env\env\bookmarks\lib\site-packages\django\template\defaulttags.py", line 312, in render
    return nodelist.render(context)
  File "C:\Users\romanpc\dev\env\env\bookmarks\lib\site-packages\django\template\base.py", line 938, in render
    bit = node.render_annotated(context)
  File "C:\Users\romanpc\dev\env\env\bookmarks\lib\site-packages\django\template\base.py", line 905, in render_annotated
    return self.render(context)
  File "C:\Users\romanpc\dev\env\env\bookmarks\lib\site-packages\django\template\defaulttags.py", line 446, in render
    url = reverse(view_name, args=args, kwargs=kwargs, current_app=current_app)
  File "C:\Users\romanpc\dev\env\env\bookmarks\lib\site-packages\django\urls\base.py", line 83, in reverse
    raise NoReverseMatch("%s is not a registered namespace" % key)
django.urls.exceptions.NoReverseMatch: 'images' is not a registered namespace
[18/Oct/2020 18:12:56] "GET /account/register/ HTTP/1.1" 500 148304
[18/Oct/2020 18:13:02] "GET /account/edit HTTP/1.1" 301 0
Internal Server Error: /account/edit/
Traceback (most recent call last):
  File "C:\Users\romanpc\dev\env\env\bookmarks\lib\site-packages\django\core\handlers\exception.py", line 47, in inner
    response = get_response(request)
  File "C:\Users\romanpc\dev\env\env\bookmarks\lib\site-packages\django\core\handlers\base.py", line 179, in _get_response
    response = wrapped_callback(request, *callback_args, **callback_kwargs)
  File "C:\Users\romanpc\dev\env\env\bookmarks\lib\site-packages\django\contrib\auth\decorators.py", line 21, in _wrapped_view
    return view_func(request, *args, **kwargs)
  File "C:\Users\romanpc\dev\env\env\bookmarks\bookmarks\account\views.py", line 83, in edit
    instance=request.user.profile)
  File "C:\Users\romanpc\dev\env\env\bookmarks\lib\site-packages\django\utils\functional.py", line 241, in inner
    return func(self._wrapped, *args)
  File "C:\Users\romanpc\dev\env\env\bookmarks\lib\site-packages\django\db\models\fields\related_descriptors.py", line 421, in __get__
    raise self.RelatedObjectDoesNotExist(
django.contrib.auth.models.User.profile.RelatedObjectDoesNotExist: User has no profile.
[18/Oct/2020 18:13:02] "GET /account/edit/ HTTP/1.1" 500 76582
(bookmarks) PS C:\Users\romanpc\dev\env\env\bookmarks\bookmarks> python manage.py runserver
Watching for file changes with StatReloader
Performing system checks...

System check identified no issues (0 silenced).
October 18, 2020 - 18:21:55
Django version 3.1.2, using settings 'bookmarks.settings'
Starting development server at http://127.0.0.1:8000/
Quit the server with CTRL-BREAK.
Internal Server Error: /account/edit/
Traceback (most recent call last):
  File "C:\Users\romanpc\dev\env\env\bookmarks\lib\site-packages\django\core\handlers\exception.py", line 47, in inner
    response = get_response(request)
  File "C:\Users\romanpc\dev\env\env\bookmarks\lib\site-packages\django\core\handlers\base.py", line 179, in _get_response
    response = wrapped_callback(request, *callback_args, **callback_kwargs)
  File "C:\Users\romanpc\dev\env\env\bookmarks\lib\site-packages\django\contrib\auth\decorators.py", line 21, in _wrapped_view
    return view_func(request, *args, **kwargs)
  File "C:\Users\romanpc\dev\env\env\bookmarks\bookmarks\account\views.py", line 84, in edit
    instance=request.user.profile)
  File "C:\Users\romanpc\dev\env\env\bookmarks\lib\site-packages\django\utils\functional.py", line 241, in inner
    return func(self._wrapped, *args)
  File "C:\Users\romanpc\dev\env\env\bookmarks\lib\site-packages\django\db\models\fields\related_descriptors.py", line 421, in __get__
    raise self.RelatedObjectDoesNotExist(
django.contrib.auth.models.User.profile.RelatedObjectDoesNotExist: User has no profile.
[18/Oct/2020 18:22:10] "GET /account/edit/ HTTP/1.1" 500 76719
C:\Users\romanpc\Dev\env\env\bookmarks\bookmarks\bookmarks\settings.py changed, reloading.
Watching for file changes with StatReloader
Performing system checks...

System check identified no issues (0 silenced).
October 18, 2020 - 18:25:55
Django version 3.1.2, using settings 'bookmarks.settings'
Starting development server at http://127.0.0.1:8000/
Quit the server with CTRL-BREAK.
(bookmarks) PS C:\Users\romanpc\dev\env\env\bookmarks\bookmarks> pip install social-auth-app-django==3.1.0
Collecting social-auth-app-django==3.1.0
  Downloading social_auth_app_django-3.1.0-py3-none-any.whl (23 kB)
Collecting social-auth-core>=1.2.0
  Downloading social_auth_core-3.3.3-py3-none-any.whl (326 kB)
     |████████████████████████████████| 326 kB 2.2 MB/s
Collecting six
  Using cached six-1.15.0-py2.py3-none-any.whl (10 kB)
Collecting requests-oauthlib>=0.6.1
  Downloading requests_oauthlib-1.3.0-py2.py3-none-any.whl (23 kB)
Collecting python3-openid>=3.0.10; python_version >= "3.0"
  Downloading python3_openid-3.2.0-py3-none-any.whl (133 kB)
     |████████████████████████████████| 133 kB ...
Collecting requests>=2.9.1
  Using cached requests-2.24.0-py2.py3-none-any.whl (61 kB)
Collecting PyJWT>=1.4.0
  Downloading PyJWT-1.7.1-py2.py3-none-any.whl (18 kB)
Collecting cryptography>=1.4
  Downloading cryptography-3.1.1-cp38-cp38-win_amd64.whl (1.5 MB)
     |████████████████████████████████| 1.5 MB 3.3 MB/s
Collecting oauthlib>=1.0.3
  Downloading oauthlib-3.1.0-py2.py3-none-any.whl (147 kB)
     |████████████████████████████████| 147 kB 6.4 MB/s
Collecting defusedxml>=0.5.0rc1; python_version >= "3.0"
  Downloading defusedxml-0.7.0rc1-py2.py3-none-any.whl (25 kB)
Collecting urllib3!=1.25.0,!=1.25.1,<1.26,>=1.21.1
  Using cached urllib3-1.25.10-py2.py3-none-any.whl (127 kB)
Collecting certifi>=2017.4.17
  Using cached certifi-2020.6.20-py2.py3-none-any.whl (156 kB)
Collecting chardet<4,>=3.0.2
  Using cached chardet-3.0.4-py2.py3-none-any.whl (133 kB)
Collecting idna<3,>=2.5
  Using cached idna-2.10-py2.py3-none-any.whl (58 kB)
Collecting cffi!=1.11.3,>=1.8
  Downloading cffi-1.14.3-cp38-cp38-win_amd64.whl (179 kB)
     |████████████████████████████████| 179 kB 6.8 MB/s
Collecting pycparser
  Downloading pycparser-2.20-py2.py3-none-any.whl (112 kB)
     |████████████████████████████████| 112 kB ...
Installing collected packages: oauthlib, urllib3, certifi, chardet, idna, requests, requests-oauthlib, defusedxml, python3-openid, PyJWT, six, pycparser, cffi, cryptography, social-auth-core, social-auth-app-django
Successfully installed PyJWT-1.7.1 certifi-2020.6.20 cffi-1.14.3 chardet-3.0.4 cryptography-3.1.1 defusedxml-0.7.0rc1 idna-2.10 oauthlib-3.1.0 pycparser-2.20 python3-openid-3.2.0 requests-2.24.0 requests-oauthlib-1.3.0 six-1.15.0 social-auth-app-django-3.1.0 social-auth-core-3.3.3 urllib3-1.25.10
WARNING: You are using pip version 20.1.1; however, version 20.2.4 is available.
You should consider upgrading via the 'c:\users\romanpc\dev\env\env\bookmarks\scripts\python.exe -m pip install --upgrade pip' command.
(bookmarks) PS C:\Users\romanpc\dev\env\env\bookmarks\bookmarks> python manage.py migrate
Operations to perform:
  Apply all migrations: account, admin, auth, contenttypes, sessions, social_django
Running migrations:
  Applying social_django.0001_initial... OK
  Applying social_django.0002_add_related_name... OK
  Applying social_django.0003_alter_email_max_length... OK
  Applying social_django.0004_auto_20160423_0400... OK
  Applying social_django.0005_auto_20160727_2333... OK
  Applying social_django.0006_partial... OK
  Applying social_django.0007_code_timestamp... OK
  Applying social_django.0008_partial_timestamp... OK
(bookmarks) PS C:\Users\romanpc\dev\env\env\bookmarks\bookmarks> python manage.py runserver
Watching for file changes with StatReloader
Performing system checks...

System check identified no issues (0 silenced).
October 18, 2020 - 18:34:07
Django version 3.1.2, using settings 'bookmarks.settings'
Starting development server at http://127.0.0.1:8000/
Quit the server with CTRL-BREAK.
(bookmarks) PS C:\Users\romanpc\dev\env\env\bookmarks\bookmarks> python manage.py runserver
Watching for file changes with StatReloader
Performing system checks...

System check identified no issues (0 silenced).
October 18, 2020 - 18:34:46
Django version 3.1.2, using settings 'bookmarks.settings'
Starting development server at http://127.0.0.1:8000/
Quit the server with CTRL-BREAK.
(bookmarks) PS C:\Users\romanpc\dev\env\env\bookmarks\bookmarks> pip install django-extensions==2.2.5
Collecting django-extensions==2.2.5
  Downloading django_extensions-2.2.5-py2.py3-none-any.whl (223 kB)
     |████████████████████████████████| 223 kB 2.2 MB/s
Requirement already satisfied: six>=1.2 in c:\users\romanpc\dev\env\env\bookmarks\lib\site-packages (from django-extensions==2.2.5) (1.15.0)
Installing collected packages: django-extensions
Successfully installed django-extensions-2.2.5
WARNING: You are using pip version 20.1.1; however, version 20.2.4 is available.
You should consider upgrading via the 'c:\users\romanpc\dev\env\env\bookmarks\scripts\python.exe -m pip install --upgrade pip' command.
(bookmarks) PS C:\Users\romanpc\dev\env\env\bookmarks\bookmarks> pip install werkzeug==0.16.0
Collecting werkzeug==0.16.0
  Downloading Werkzeug-0.16.0-py2.py3-none-any.whl (327 kB)
     |████████████████████████████████| 327 kB 2.2 MB/s
Installing collected packages: werkzeug
Successfully installed werkzeug-0.16.0
WARNING: You are using pip version 20.1.1; however, version 20.2.4 is available.
You should consider upgrading via the 'c:\users\romanpc\dev\env\env\bookmarks\scripts\python.exe -m pip install --upgrade pip' command.
(bookmarks) PS C:\Users\romanpc\dev\env\env\bookmarks\bookmarks> pip install pyOpenSSL==19.0.0
Collecting pyOpenSSL==19.0.0
  Downloading pyOpenSSL-19.0.0-py2.py3-none-any.whl (53 kB)
     |████████████████████████████████| 53 kB 341 kB/s
Requirement already satisfied: cryptography>=2.3 in c:\users\romanpc\dev\env\env\bookmarks\lib\site-packages (from pyOpenSSL==19.0.0) (3.1.1)
Requirement already satisfied: six>=1.5.2 in c:\users\romanpc\dev\env\env\bookmarks\lib\site-packages (from pyOpenSSL==19.0.0) (1.15.0)
Requirement already satisfied: cffi!=1.11.3,>=1.8 in c:\users\romanpc\dev\env\env\bookmarks\lib\site-packages (from cryptography>=2.3->pyOpenSSL==19.0.0) (1.14.3)
Requirement already satisfied: pycparser in c:\users\romanpc\dev\env\env\bookmarks\lib\site-packages (from cffi!=1.11.3,>=1.8->cryptography>=2.3->pyOpenSSL==19.0.0) (2.20)
Installing collected packages: pyOpenSSL
Successfully installed pyOpenSSL-19.0.0
WARNING: You are using pip version 20.1.1; however, version 20.2.4 is available.
You should consider upgrading via the 'c:\users\romanpc\dev\env\env\bookmarks\scripts\python.exe -m pip install --upgrade pip' command.
(bookmarks) PS C:\Users\romanpc\dev\env\env\bookmarks\bookmarks> python manage.py runserver_plus --cert-file cert.crt
 * Restarting with stat
Performing system checks...

System check identified no issues (0 silenced).

Django version 3.1.2, using settings 'bookmarks.settings'
Development server is running at https://[127.0.0.1]:8000/
Using the Werkzeug debugger (http://werkzeug.pocoo.org/)
Quit the server with CTRL-BREAK.
 * Debugger is active!
 * Debugger PIN: 232-097-404
 * Running on https://127.0.0.1:8000/ (Press CTRL+C to quit)
127.0.0.1 - - [18/Oct/2020 18:37:49] "GET /account HTTP/1.1" 301 -
127.0.0.1 - - [18/Oct/2020 18:37:49] "GET /account/ HTTP/1.1" 302 -
127.0.0.1 - - [18/Oct/2020 18:37:49] "GET /account/login/?next=/account/ HTTP/1.1" 200 -
127.0.0.1 - - [18/Oct/2020 18:37:49] "GET /static/css/base.css HTTP/1.1" 200 -
Not Found: /favicon.ico
127.0.0.1 - - [18/Oct/2020 18:37:49] "GET /favicon.ico HTTP/1.1" 404 -
 * Detected change in 'C:\\Users\\romanpc\\dev\\env\\env\\bookmarks\\bookmarks\\bookmarks\\settings.py', reloading
 * Restarting with stat
Performing system checks...

System check identified no issues (0 silenced).

Django version 3.1.2, using settings 'bookmarks.settings'
Development server is running at https://[127.0.0.1]:8000/
Using the Werkzeug debugger (http://werkzeug.pocoo.org/)
Quit the server with CTRL-BREAK.
 * Debugger is active!
 * Debugger PIN: 232-097-404
 * Running on https://127.0.0.1:8000/ (Press CTRL+C to quit)
 * Detected change in 'C:\\Users\\romanpc\\dev\\env\\env\\bookmarks\\bookmarks\\bookmarks\\settings.py', reloading
 * Restarting with stat
Performing system checks...

System check identified no issues (0 silenced).

Django version 3.1.2, using settings 'bookmarks.settings'
Development server is running at https://[127.0.0.1]:8000/
Using the Werkzeug debugger (http://werkzeug.pocoo.org/)
Quit the server with CTRL-BREAK.
 * Debugger is active!
 * Debugger PIN: 232-097-404
 * Running on https://127.0.0.1:8000/ (Press CTRL+C to quit)
 * Detected change in 'C:\\Users\\romanpc\\dev\\env\\env\\bookmarks\\bookmarks\\bookmarks\\settings.py', reloading
 * Restarting with stat
Performing system checks...

System check identified no issues (0 silenced).

Django version 3.1.2, using settings 'bookmarks.settings'
Development server is running at https://[127.0.0.1]:8000/
Using the Werkzeug debugger (http://werkzeug.pocoo.org/)
Quit the server with CTRL-BREAK.
 * Debugger is active!
 * Debugger PIN: 232-097-404
 * Running on https://127.0.0.1:8000/ (Press CTRL+C to quit)
 * Detected change in 'C:\\Users\\romanpc\\dev\\env\\env\\bookmarks\\bookmarks\\bookmarks\\settings.py', reloading
 * Restarting with stat
Performing system checks...

System check identified no issues (0 silenced).

Django version 3.1.2, using settings 'bookmarks.settings'
Development server is running at https://[127.0.0.1]:8000/
Using the Werkzeug debugger (http://werkzeug.pocoo.org/)
Quit the server with CTRL-BREAK.
 * Debugger is active!
 * Debugger PIN: 232-097-404
 * Running on https://127.0.0.1:8000/ (Press CTRL+C to quit)
 * Detected change in 'C:\\Users\\romanpc\\dev\\env\\env\\bookmarks\\bookmarks\\bookmarks\\settings.py', reloading
 * Restarting with stat
Performing system checks...

System check identified no issues (0 silenced).

Django version 3.1.2, using settings 'bookmarks.settings'
Development server is running at https://[127.0.0.1]:8000/
Using the Werkzeug debugger (http://werkzeug.pocoo.org/)
Quit the server with CTRL-BREAK.
 * Debugger is active!
 * Debugger PIN: 232-097-404
 * Running on https://127.0.0.1:8000/ (Press CTRL+C to quit)
(bookmarks) PS C:\Users\romanpc\dev\env\env\bookmarks\bookmarks> python manage.py runserver_plus --cert-file cert.crt
 * Restarting with stat
Performing system checks...

System check identified no issues (0 silenced).

Django version 3.1.2, using settings 'bookmarks.settings'
Development server is running at https://[127.0.0.1]:8000/
Using the Werkzeug debugger (http://werkzeug.pocoo.org/)
Quit the server with CTRL-BREAK.
 * Debugger is active!
 * Debugger PIN: 232-097-404
 * Running on https://127.0.0.1:8000/ (Press CTRL+C to quit)
127.0.0.1 - - [18/Oct/2020 19:00:30] "GET /account/login/?next=/account/ HTTP/1.1" 200 -
127.0.0.1 - - [18/Oct/2020 19:00:30] "GET /static/css/base.css HTTP/1.1" 200 -
127.0.0.1 - - [18/Oct/2020 19:00:31] "GET /social-auth/login/facebook/ HTTP/1.1" 302 -
127.0.0.1 - - [18/Oct/2020 19:00:33] "GET /account/login/?next=/account/ HTTP/1.1" 200 -
127.0.0.1 - - [18/Oct/2020 19:00:33] "GET /static/css/base.css HTTP/1.1" 200 -
 * Detected change in 'C:\\Users\\romanpc\\dev\\env\\env\\bookmarks\\bookmarks\\bookmarks\\settings.py', reloading
 * Restarting with stat
Performing system checks...

System check identified no issues (0 silenced).

Django version 3.1.2, using settings 'bookmarks.settings'
Development server is running at https://[127.0.0.1]:8000/
Using the Werkzeug debugger (http://werkzeug.pocoo.org/)
Quit the server with CTRL-BREAK.
 * Debugger is active!
 * Debugger PIN: 232-097-404
 * Running on https://127.0.0.1:8000/ (Press CTRL+C to quit)
(bookmarks) PS C:\Users\romanpc\dev\env\env\bookmarks\bookmarks>


